Workbook

Sheet 읽어주세요
A1: 쏠 타로 하우스 — 미리 써 두는 문장 DB
A2: 기준 데이터: tarot_data.json v2.5 (2026-10-07). 모든 문장은 Claude 초안이며 상담사 검수 전입니다. 결과 리포트는 이 문장들을 서버가 조립하고, AI는 고민 맞춤 한 줄·질문·이야기만 짧게 씁니다.
A4: 쓰는 법
A5: 1. 시트 하나를 열고 '현재 문장'을 읽습니다. 노란 칸(상태 · 수정안 · 검수 메모)만 고쳐 주세요.
A6: 2. 그대로 써도 되면 상태를 '확정'으로 바꿉니다. 고칠 문장은 '수정안'에 새 문장을 쓰고 상태를 '확정'으로 둡니다.
A7: 3. 직접 고치기 어렵거나 의견만 남길 때는 상태 '수정요청' + '검수 메모'에 이유를 적어 주세요.
A8: 4. '현재 문장'과 ID 칸은 고치지 마세요. 수정안이 있으면 수정안이, 없으면 현재 문장이 최종 문장이 됩니다.
A9: 5. {name} · {nickname} 같은 중괄호는 닉네임 등이 들어갈 자리라 그대로 남겨 주세요.
A10: 6. '분량 확인'이 뜨면 기준 글자 수를 벗어난 문장이에요. 꼭 맞출 필요는 없지만 화면에서 너무 길거나 짧을 수 있어요.
A11: 7. 다 끝나면 파일을 돌려주세요. 개발 쪽에서 import_db.py로 tarot_data.json에 한 번에 반영합니다(확정만 반영하는 옵션 있음).
A13: 색 · 상태
A14: 노란 칸 | B14: 검수자가 쓰는 칸 (상태 · 수정안 · 검수 메모)
A15: 확정 | B15: 이대로 결과에 쓴다 (수정안이 있으면 수정안으로)
A16: 수정요청 | B16: 고쳐야 하지만 수정안을 아직 못 씀 — 메모 확인
A17: 검수중 | B17: 읽는 중, 나중에 다시 봄
A18: 초안 | B18: 아직 안 봄 (처음 상태)
A19: 삭제 | B19: 이 문장을 빼고 싶음 — 개발 쪽과 구조를 함께 바꿔야 해서 자동 반영되지 않음
A21: 작성 예시 (실제 시트와 같은 칸 구성)
A22: ID | B22: 카드 · 분류 | C22: 항목 | D22: 현재 문장 (초안) | F22: 상태 | G22: 수정안 | I22: 검수 메모
A23: cards.12.positions.now | B23: 12 바위 위의 쉼 · 물범 | C23: 지금의 마음 · 정방향 | D23: 몸도 마음도 쉬고 싶다는 신호를 보내고 있어요. 열심히 해 왔는데 생각만큼 앞으로 나아가지 않는 느낌이 들 수 있어요. | F23: 확정 | G23: 몸도 마음도 잠시 쉬어 가자는 신호를 보내고 있어요. 열심히 달려왔는데 제자리인 것 같은 느낌이 들 수 있어요. | I23: '나아가지 않는'이 실패처럼 들려서 '제자리인 것 같은'으로 부드럽게
A25: 진행 현황 (자동 계산)
A26: 시트 | B26: 무엇인가 | C26: 결과에서 쓰이는 곳 | D26: 단계 | E26: 문장 수 | F26: 확정 | G26: 수정요청 | H26: 초안 | I26: 확정 비율 | J26: 분량 확인
A27: 위치해석 | B27: 카드 22장 × 위치 3곳 × 정·역방향 해석 | C27: 결과 2·3·4번 카드 섹션 본문 | D27: 출시 1단계 | E27: =COUNTA(위치해석!A:A)-1 -> 132 | F27: =COUNTIF(위치해석!E:E,"확정") -> 0 | G27: =COUNTIF(위치해석!E:E,"수정요청") -> 0 | H27: =COUNTIF(위치해석!E:E,"초안") -> 132 | I27: =IF(E27=0,0,F27/E27) -> 0 | J27: =COUNTIF(위치해석!I:I,"분량 확인") -> 0
A28: 깊이읽기 | B28: 카드 22장 × 위치 3곳 × 단락 2개 + 역방향 공통 3개 | C28: 결과 2·3·4번 '조금 더 들여다보기' | D28: 2단계 → 초안 완료 | E28: =COUNTA(깊이읽기!A:A)-1 -> 198 | F28: =COUNTIF(깊이읽기!E:E,"확정") -> 0 | G28: =COUNTIF(깊이읽기!E:E,"수정요청") -> 0 | H28: =COUNTIF(깊이읽기!E:E,"초안") -> 198 | I28: =IF(E28=0,0,F28/E28) -> 0 | J28: =COUNTIF(깊이읽기!I:I,"분량 확인") -> 0
A29: 핵심메시지 | B29: 카드별 핵심 메시지 정·역방향 | C29: 결과 2·3·4번 카드명 아래 한 줄 | D29: 출시 1단계 | E29: =COUNTA(핵심메시지!A:A)-1 -> 44 | F29: =COUNTIF(핵심메시지!E:E,"확정") -> 0 | G29: =COUNTIF(핵심메시지!E:E,"수정요청") -> 0 | H29: =COUNTIF(핵심메시지!E:E,"초안") -> 44 | I29: =IF(E29=0,0,F29/E29) -> 0 | J29: =COUNTIF(핵심메시지!I:I,"분량 확인") -> 0
A30: 카드설명 | B30: 카드별 '어떤 카드인가요' 두 문장 | C30: 결과 1번 세 장 한눈에 + 카드 섹션 '어떤 카드인가요' | D30: 출시 1단계 | E30: =COUNTA(카드설명!A:A)-1 -> 44 | F30: =COUNTIF(카드설명!E:E,"확정") -> 0 | G30: =COUNTIF(카드설명!E:E,"수정요청") -> 0 | H30: =COUNTIF(카드설명!E:E,"초안") -> 44 | I30: =IF(E30=0,0,F30/E30) -> 0 | J30: =COUNTIF(카드설명!I:I,"분량 확인") -> 0
A31: 상황질문 | B31: 카드별 기본 질문 2개 (AI 맞춤 질문이 없을 때) | C31: 결과 2·3·4번 질문 2개 | D31: 출시 1단계 | E31: =COUNTA(상황질문!A:A)-1 -> 88 | F31: =COUNTIF(상황질문!E:E,"확정") -> 0 | G31: =COUNTIF(상황질문!E:E,"수정요청") -> 0 | H31: =COUNTIF(상황질문!E:E,"초안") -> 88 | I31: =IF(E31=0,0,F31/E31) -> 0 | J31: =COUNTIF(상황질문!I:I,"분량 확인") -> 0
A32: 마무리 | B32: 세 번째 카드로 나왔을 때 마무리 문장 | C32: 결과 5번 이야기 뒤 | D32: 출시 1단계 | E32: =COUNTA(마무리!A:A)-1 -> 44 | F32: =COUNTIF(마무리!E:E,"확정") -> 0 | G32: =COUNTIF(마무리!E:E,"수정요청") -> 0 | H32: =COUNTIF(마무리!E:E,"초안") -> 44 | I32: =IF(E32=0,0,F32/E32) -> 0 | J32: =COUNTIF(마무리!I:I,"분량 확인") -> 0
A33: 실천카드 | B33: 카드별 실천 3개 × 제목·방법·시간·이유 | C33: 결과 7번 이번 주 실천 카드 | D33: 출시 1단계 | E33: =COUNTA(실천카드!A:A)-1 -> 264 | F33: =COUNTIF(실천카드!E:E,"확정") -> 0 | G33: =COUNTIF(실천카드!E:E,"수정요청") -> 0 | H33: =COUNTIF(실천카드!E:E,"초안") -> 264 | I33: =IF(E33=0,0,F33/E33) -> 0 | J33: =COUNTIF(실천카드!I:I,"분량 확인") -> 0
A34: 웰니스처방 | B34: 고민 영역×필요 36 + 필요별 6 × 제목·방법·이유 | C34: 결과 6번 웰니스 처방 | D34: 출시 1단계 | E34: =COUNTA(웰니스처방!A:A)-1 -> 126 | F34: =COUNTIF(웰니스처방!E:E,"확정") -> 0 | G34: =COUNTIF(웰니스처방!E:E,"수정요청") -> 0 | H34: =COUNTIF(웰니스처방!E:E,"초안") -> 126 | I34: =IF(E34=0,0,F34/E34) -> 0 | J34: =COUNTIF(웰니스처방!I:I,"분량 확인") -> 3
A35: 대체문장 | B35: AI가 실패하거나 고민을 적지 않았을 때 5번에 들어가는 문장 — 고민 영역별 2개 | C35: 결과 5번 이야기·내 고민에 대어 보면 | D35: v2.5 신규 | E35: =COUNTA(대체문장!A:A)-1 -> 28 | F35: =COUNTIF(대체문장!E:E,"확정") -> 0 | G35: =COUNTIF(대체문장!E:E,"수정요청") -> 0 | H35: =COUNTIF(대체문장!E:E,"초안") -> 28 | I35: =IF(E35=0,0,F35/E35) -> 0 | J35: =COUNTIF(대체문장!I:I,"분량 확인") -> 0
A36: 안전키워드 | B36: 고민 원문에서 찾는 위험·주의·폭력 신호 단어 (한 칸에 쉼표로) | C36: 고민 제출 직후 안전 확인 | D36: v2.5 신규 | E36: =COUNTA(안전키워드!A:A)-1 -> 5 | F36: =COUNTIF(안전키워드!E:E,"확정") -> 0 | G36: =COUNTIF(안전키워드!E:E,"수정요청") -> 0 | H36: =COUNTIF(안전키워드!E:E,"초안") -> 5 | I36: =IF(E36=0,0,F36/E36) -> 0 | J36: =COUNTIF(안전키워드!I:I,"분량 확인") -> 0
A37: 감정문장 | B37: 감정 8개 × 한 문장 | C37: 결과 2번 첫 번째 카드 섹션 | D37: 출시 1단계 | E37: =COUNTA(감정문장!A:A)-1 -> 8 | F37: =COUNTIF(감정문장!E:E,"확정") -> 0 | G37: =COUNTIF(감정문장!E:E,"수정요청") -> 0 | H37: =COUNTIF(감정문장!E:E,"초안") -> 8 | I37: =IF(E37=0,0,F37/E37) -> 0 | J37: =COUNTIF(감정문장!I:I,"분량 확인") -> 0
A38: 화면문구 | B38: 인트로부터 결과까지 화면에 보이는 고정 문구 | C38: 각 화면 | D38: 출시 1단계 | E38: =COUNTA(화면문구!A:A)-1 -> 71 | F38: =COUNTIF(화면문구!E:E,"확정") -> 0 | G38: =COUNTIF(화면문구!E:E,"수정요청") -> 0 | H38: =COUNTIF(화면문구!E:E,"초안") -> 71 | I38: =IF(E38=0,0,F38/E38) -> 0 | J38: =COUNTIF(화면문구!I:I,"분량 확인") -> 0
A39: 합계 | E39: =SUM(E27:E38) -> 1052 | F39: =SUM(F27:F38) -> 0 | G39: =SUM(G27:G38) -> 0 | H39: =SUM(H27:H38) -> 1052 | I39: =IF(E39=0,0,F39/E39) -> 0 | J39: =SUM(J27:J38) -> 3
A40: 깊이읽기 시트(금색 탭)는 이번에 새로 쓴 2단계 초안입니다. 역방향은 위치별 공통 단락 3개를 22장 모두에 씁니다.

Sheet 점검이력
A1: ID | B1: 구분 | C1: 처리 | D1: 무엇이 문제였나 | E1: 전 | F1: 후 (현재 문장)
A2: cards.11.deep.step.0 | B2: 우려 | C2: 반영 | D2: '단정할 수 없는 부분이 많다는 걸 알게 돼요' - 단정이고, 폭력·부당한 대우를 겪은 사람에게 '네 해석일 수 있다'는 식으로 경험을 깎아내리는 말로 읽힐 수 있음 | E2: 사실과 해석을 나누면 감정의 온도가 조금 내려가요. 실제로 일어난 일과, 그 일에 내가 붙인 의미를 따로 보면 생각보다 단정할 수 없는 부분이 많다는 걸 알게 돼요. | F2: 사실과 해석을 나누면 감정의 온도가 조금 내려가요. 실제로 일어난 일과, 그 일에 내가 붙인 의미를 따로 보면 어디까지가 사실이고 어디부터가 내 해석인지 조금 더 또렷해져요.
A3: cards.11.practices.0.why | B3: 우려 | C3: 반영 | D3: 무겁게 하던 것이 '일어난 일이 아니라 내 해석이었음'이라고 단정 — 실제로 힘든 일(폭력 등)을 겪는 사람에게 상처가 될 수 있음 | E3: 사실과 해석을 떼어 놓으면, 마음을 무겁게 하던 것이 일어난 일이 아니라 내 해석이었음을 알아차리기 쉬워져요. | F3: 사실과 해석을 떼어 놓으면, 마음을 무겁게 하던 것 중 어디까지가 일어난 일이고 어디부터가 내 해석인지 알아차리기 쉬워져요.
A4: cards.13.core | B4: 우려 | C4: 반영 | D4: '-아야 들어갈 수 있어요'가 지금 관계·직장을 떠나야 한다는 단정으로 읽힐 수 있음 | E4: 맞지 않는 껍데기를 내려놓아야 새 집에 들어갈 수 있어요. | F4: 맞지 않는 껍데기를 내려놓을 때 새 집으로 옮겨 갈 수 있어요.
A5: cards.13.reversed.core | B5: 우려 | C5: 반영 | D5: '끝내야 할 것'이 관계 종료 권유나 위기 상황에서 위험하게 읽힐 수 있음 | E5: 끝내야 할 것을 아직 놓지 못하고 있어요. | F5: 내려놓을 것을 아직 놓지 못하고 있어요.
A6: cards.15.deep.hold.0 | B6: 우려 | C6: 반영 | D6: '그 순간에는 분명 도움이 돼요' - 단정어 '분명'. 불안할 때 반복하는 습관에 자해·음주 등이 포함될 수 있어 '분명 도움이 된다'는 말은 위험 | E6: 불안할 때 반복하는 습관은 그 순간에는 분명 도움이 돼요. 그래서 계속하게 되지만, 습관이 길어지면 불안을 달래 주던 방법이 오히려 나를 붙잡는 끈이 되기도 해요. | F6: 불안할 때 반복하는 습관은 그 순간에는 잠깐 마음을 편하게 해 주기도 해요. 그래서 계속하게 되지만, 습관이 길어지면 불안을 달래 주던 방법이 오히려 나를 붙잡는 끈이 되기도 해요.
A7: cards.16.deep.step.1 | B7: 우려 | C7: 반영 | D7: '연락 하나' - 다가가기형이 아닌 문장에서 연락을 권함. 이별·관계 붕괴 고민에서 상대에게 연락하라는 뜻으로 읽힐 수 있음 | E7: 오늘 할 수 있는 가장 작은 한 조각을 정해 보세요. 연락 하나, 정리 하나, 계획 한 줄이면 충분해요. 매일 쌓은 조각을 기록해 두면, 무너진 자리 위에 무언가가 다시 자라고 있다는 걸 눈으로 확인할 수 있어요. | F7: 오늘 할 수 있는 가장 작은 한 조각을 정해 보세요. 확인 하나, 정리 하나, 계획 한 줄이면 충분해요. 매일 쌓은 조각을 기록해 두면, 무너진 자리 위에 무언가가 다시 자라고 있다는 걸 눈으로 확인할 수 있어요.
A8: cards.17.core | B8: 우려 | C8: 반영 | D8: '분명히'로 회복을 단정 | E8: 천천히, 그러나 분명히 회복은 일어나요. | F8: 천천히, 그래도 조금씩 회복은 일어날 수 있어요.
A9: cards.18.practices.1.why | B9: 우려 | C9: 반영 | D9: 걱정이 '실제보다 커져 있었음'을 전제로 단정 — 실제 위험이 있는 상황에서 위험을 축소하게 할 수 있음 | E9: 막연한 걱정을 숫자로 적으면, 머릿속 시나리오가 실제보다 커져 있었음을 알아차리기 쉬워져요. | F9: 막연한 걱정을 숫자로 적으면, 머릿속 시나리오가 실제보다 커져 있지는 않은지 살펴보기 쉬워져요.
A10: cards.21.deep.step.1 | B10: 우려 | C10: 반영 | D10: '감사의 말을 전하고 싶은 사람... 메시지를 보내 보는 것도 좋아요' - 다가가기형이 아닌 문장에서 상대에게 마음을 전하라는 제안. '함께한 것들이 다음 바다를 비춰 줄 거예요'는 예언형 | E10: 이번 여정에서 고마웠던 사람과 순간을 세 가지 적어 보세요. 감사의 말을 전하고 싶은 사람이 떠오른다면 짧은 메시지를 보내 보는 것도 좋아요. 바다 친구들이 둥글게 모이듯, 함께한 것들이 다음 바다를 비춰 줄 거예요. | F10: 이번 여정에서 고마웠던 사람과 순간을 세 가지 적어 보세요. 고마운 얼굴이 떠오른다면 마음속으로 감사의 말을 건네 보는 것도 좋아요. 바다 친구들이 둥글게 모이듯, 함께한 것들이 다음 바다를 비춰 줄 수 있어요.
A11: cards.3.practices.0.title | B11: 우려 | C11: 반영 | D11: '자기자비'는 이론 용어 | E11: 자기자비 쉼표 | F11: 나에게 다정한 쉼표
A12: cards.5.practices.0.how | B12: 우려 | C12: 다가가기형으로 분류(문장 유지) | D12: 다가가기형이 아닌데 다른 사람에게 메시지를 보내라고 함(폭력·통제 신호가 있어도 빠지지 않음)
A13: cards.5.practices.0.why | B13: 우려 | C13: 다가가기형으로 분류(문장 유지) | D13: '묻는 것 자체가 외로움을 덜어 줘요'가 연락을 전제로 함(다가가기형 아님)
A14: cards.5.reversed.core | B14: 우려 | C14: 반영 | D14: '도움을 구하는 길이 닫혀 있어요'는 위기 상황에서 절망적으로 읽힘 | E14: 도움을 구하는 길이 아직 닫혀 있어요. | F14: 도움을 구하는 문을 아직 두드리지 못하고 있어요.
A15: cards.6.deep.step.1 | B15: 우려 | C15: 반영 | D15: '관계'를 가치와 비교해 '가까운 쪽을 고르면' - 관계 하나를 두고 읽으면 관계를 유지할지 끝낼지 고르라는 권유로 읽힐 수 있음 | E15: 내가 소중히 여기는 가치 세 가지를 적고, 지금 고민 중인 관계나 선택이 그 가치와 얼마나 가까운지 살펴보세요. 가까운 쪽을 고르면, 결과와 상관없이 그 선택을 내 것으로 받아들이기가 쉬워져요. | F15: 내가 소중히 여기는 가치 세 가지를 적고, 지금 고민 중인 관계나 선택이 그 가치와 얼마나 가까운지 살펴보세요. 그 가치를 기준으로 삼으면, 결과와 상관없이 내 선택을 내 것으로 받아들이기가 쉬워져요.
A16: cards.6.practices.1.how | B16: 우려 | C16: 반영 (Claude 조정) | D16: 누구에게 전하는지 빠져 있음. 서운함·갈등을 상대에게 직접 말하게 해서, 폭력 신호를 밝히지 않은 사용자에게는 위험할 수 있음 | E16: '나는 ~할 때 ~하게 느껴져'라는 형식으로 내 마음 하나를 전해요. | F16: 편하게 말할 수 있는 사람에게 '나는 ~할 때 ~하게 느껴져'라는 형식으로 내 마음 하나를 전해요.
A17: cards.6.practices.1.title | B17: 우려 | C17: 반영 (Claude 조정) | D17: '나-전달법'은 이론·기법명(전문 용어) | E17: 나-전달법 한 문장 | F17: '나는'으로 시작하는 한 문장
A18: cards.8.closing | B18: 우려 | C18: 반영 | D18: '불편함을 품는 시간'이 상황을 견디라는 뜻으로 읽힐 수 있음 | E18: 이 세 장이 함께 말하는 한 가지는, 불편함을 품는 시간이 나를 단단하게 만드는 진주가 될 수 있다는 점이에요. | F18: 이 세 장이 함께 말하는 한 가지는, 불편한 감정을 품어 주는 시간이 나를 단단하게 만드는 진주가 될 수 있다는 점이에요.
A19: cards.8.core | B19: 우려 | C19: 반영 | D19: '불편함을 품는 시간'이 상황(폭력 등)을 참으라는 뜻으로 읽힐 수 있음 | E19: 불편함을 품는 시간이 단단함을 만들어요. | F19: 불편한 감정을 품어 주는 시간이 단단함을 만들어요.
A20: cards.8.deep.now.0 | B20: 우려 | C20: 반영 | D20: '견뎌 온 당신의 마음은 이미 꽤 단단해져 있어요' - '당신' 호칭에 단정, 참고 견디는 것을 칭찬해 폭력·학대 상황에서 계속 견디라는 뜻으로 읽힐 수 있음. 역방향 위치해석('견디는 것만이 강한 거라는 생각이 도움을 청하는 길을 막고')과도 결이 부딪힘 | E20: 드러내지 않은 불편함을 품고 하루를 지켜 낸다는 건 생각보다 많은 힘이 드는 일이에요. 아무도 몰라도, 그 시간을 견뎌 온 당신의 마음은 이미 꽤 단단해져 있어요. | F20: 드러내지 않은 불편함을 품고 하루를 지켜 낸다는 건 생각보다 많은 힘이 드는 일이에요. 아무도 몰라도, 그 시간을 지나온 내 마음의 수고는 충분히 알아줄 만해요.
A21: cards.8.deep.step.0 | B21: 우려 | C21: 반영 | D21: '해결하지 못하는 시간이 오히려 마음의 결을 단단하게 다듬어 줘요' - 단정이고, 고통을 견디는 시간이 이롭다는 뜻으로 읽혀 위기·폭력 상황에서 부적절할 수 있음 | E21: 조개는 모래알을 뱉어 내지 못할 때 그것을 감싸 진주로 만들어요. 불편함과 함께 있는 연습도 비슷해서, 감정을 바로 해결하지 못하는 시간이 오히려 마음의 결을 단단하게 다듬어 줘요. | F21: 조개는 모래알을 뱉어 내지 못할 때 그것을 감싸 진주로 만들어요. 불편함과 함께 있는 연습도 비슷해서, 감정을 바로 해결하지 못하는 시간이 마음의 결을 단단하게 다듬어 줄 수 있어요.
A22: cards.8.positions.now | B22: 우려 | C22: 반영 | D22: 견디는 것 자체를 힘으로 칭찬해 폭력 상황에서 '참아라'로 읽힐 수 있음, '당신' 사용 | E22: 쉽게 드러내지 않지만 마음속에 꽤 오래 품고 있는 불편함이 있어요. 그걸 견디며 하루를 지켜 내고 있는 것 자체가 당신의 힘이에요. | F22: 쉽게 드러내지 않지만 마음속에 꽤 오래 품고 있는 불편함이 있어요. 그 마음을 안고 하루를 지내 온 것만으로도 이미 애쓰고 있는 거예요.
A23: copy.safety.urgent_contacts.0.note | B23: 우려 | C23: 반영 (Claude 조정) | D23: 노출 문구에 '[확인필요: 출시 전 최신 번호 확인]' 내부 메모 포함(contacts.1.note도 동일) | E23: 24시간 [확인필요: 출시 전 최신 번호 확인] | F23: 24시간
A24: copy.safety.urgent_contacts.0.number | B24: 우려 | C24: 판단 필요 | D24: 화면에 보이던 내부 메모 '[확인필요]'는 뺐음. 109·1577-0199 번호는 출시 전 최신 확인 필요
A25: copy.safety.violence_box | B25: 우려 | C25: 반영 (Claude 조정) | D25: 사용자 노출 문구 안에 '[확인필요]' 표기가 들어 있고, 여성긴급전화만 안내해 성별을 가정함 | E25: 혹시 상대가 무섭게 느껴지거나 통제받는다고 느낀다면, 그건 혼자 해결해야 할 고민이 아니에요. 여성긴급전화 1366(24시간), 긴급 시 112에서 도움받을 수 있어요. [확인필요] | F25: 혹시 상대가 무섭게 느껴지거나 통제받는다고 느낀다면, 그건 혼자 해결해야 할 고민이 아니에요. 여성긴급전화 1366(24시간), 긴급 시 112에서 도움받을 수 있어요.
A26: copy.safety.violence_box | B26: 우려 | C26: 판단 필요 | D26: 1366(여성긴급전화)만 안내해 피해자를 여성으로 가정할 수 있음. 성별과 상관없는 안내를 함께 둘지 결정 필요. 번호는 출시 전 확인
A27: prescriptions.by_domain_need.FAM_BOUNDARY.how | B27: 우려 | C27: 다가가기형으로 분류(문장 유지) | D27: 다가가기형이 아닌데 간섭하는 가족에게 직접 선을 긋는 말을 하도록 제안
A28: cards.0.practices.1.how | B28: 오류 | C28: 반영 | D28: 하나를 적고 '그중 하나'를 고르라고 해서 앞뒤가 맞지 않음 | E28: 오늘 궁금했던 것 하나를 메모장에 적고, 그중 하나를 10분만 찾아봐요. | F28: 오늘 궁금했던 것 몇 가지를 메모장에 적고, 그중 하나를 10분만 찾아봐요.
A29: cards.19.deep.now.0 | B29: 오류 | C29: 반영 | D29: '웃을 수 있는 순간은 ~가볍게 여겨서가 아니라, ~힘이 되어 줘요' - '-서가 아니라' 뒤에 짝이 맞지 않는 서술어가 와 비문 | E29: 고민이 있는데도 기쁨과 기대가 살아 있다는 건, 마음에 회복할 힘이 충분히 남아 있다는 뜻이에요. 웃을 수 있는 순간은 고민을 가볍게 여겨서가 아니라, 그 고민을 견딜 힘이 되어 줘요. | F29: 고민이 있는데도 기쁨과 기대가 살아 있다는 건, 마음에 회복할 힘이 충분히 남아 있다는 뜻이에요. 웃을 수 있는 건 고민을 가볍게 여겨서가 아니에요. 그런 순간이 오히려 그 고민을 견딜 힘이 되어 줘요.
A30: cards.3.deep.now.0 | B30: 오류 | C30: 반영 | D30: 한 문장 안에서 '당신이 가진 큰 힘'과 '내 쪽 그릇'이 섞임(BRIEF의 예시와 같은 유형). 위치해석 문장('그 따뜻함이 당신의 큰 힘이지만')도 거의 그대로 반복 | E30: 누군가를 돌보는 일은 마음을 꽤 많이 쓰는 일이에요. 그 따뜻함은 당신이 가진 큰 힘이지만, 쓴 만큼 채워지지 않으면 어느새 내 쪽 그릇이 비어 가기도 해요. | F30: 누군가를 돌보는 일은 마음을 꽤 많이 쓰는 일이에요. 그 따뜻함은 큰 힘이지만, 쓴 만큼 채워지지 않으면 어느새 내 쪽 그릇이 비어 가기도 해요.
A31: cards.3.positions.now | B31: 오류 | C31: 반영 (Claude 조정) | D31: 한 문장 안에 '당신'과 '나'가 섞임(기준 예시와 동일) | E31: 누군가를 챙기고 돌보느라 마음을 많이 쓰고 있어요. 그 따뜻함이 당신의 큰 힘이지만, 정작 나를 돌볼 여유는 줄어 있을 수 있어요. | F31: 누군가를 챙기고 돌보느라 마음을 많이 쓰고 있어요. 그 따뜻함은 큰 힘이지만, 정작 나를 돌볼 여유는 줄어 있을 수 있어요.
A32: cards.4.practices.1.how | B32: 오류 | C32: 반영 | D32: '잠자리를 해요'로 읽혀 뜻이 어색함(성관계로도 읽힘), '이번 주는'도 어색 | E32: 기상, 식사, 잠자리 중 하나를 골라 이번 주는 같은 시간에 해요. | F32: 기상, 식사, 잠자리에 드는 시간 중 하나를 골라 이번 주에는 매일 같은 시간에 해요.
A33: cards.7.positions.step | B33: 오류 | C33: 반영 | D33: '잘 되고' 띄어쓰기 | E33: 방향을 하나로 정하고 흐름을 이용해 보세요. 돌고래가 파도를 거스르지 않고 그 힘을 빌려 나아가듯, 이미 잘 되고 있는 흐름에 힘을 실어 보는 거예요. | F33: 방향을 하나로 정하고 흐름을 이용해 보세요. 돌고래가 파도를 거스르지 않고 그 힘을 빌려 나아가듯, 이미 잘되고 있는 흐름에 힘을 실어 보는 거예요.
A34: cards.7.practices.2.title | B34: 오류 | C34: 반영 (Claude 조정) | D34: '잘되다'는 한 단어 | E34: 잘 된 흐름 찾기 | F34: 잘 풀린 흐름 찾기
A35: cards.7.practices.2.why | B35: 오류 | C35: 반영 (Claude 조정) | D35: '잘되다'는 한 단어 | E35: 이미 잘 된 경험에서 조건을 찾으면, 새로 애쓰기보다 그 흐름을 다시 만들 수 있어요. | F35: 이미 잘 풀린 경험에서 조건을 찾으면, 새로 애쓰기보다 그 흐름을 다시 만들 수 있어요.
A36: copy.first_time.body | B36: 오류 | C36: 제안만(문구 유지) | D36: '한 번'(시도의 뜻은 '한번'), '비춰 주는지 들어봅시다' 감각 불일치, '타로 카드가 설명하는 현재 상황에 적절한' 번역투, '쏠 하우스' 명칭 불일치 | F36: 오늘 {nickname}님의 고민을 타로카드가 어떻게 비춰 주는지 함께 살펴봐요. 쏠 타로 하우스만의 특제 레시피로 {nickname}님의 카드가 비춰 준 지금 상황에 맞는 웰니스 제안을 해 드릴게요. 이제 한번 해 볼까요?
A37: copy.intro.button | B37: 오류 | C37: 제안만(문구 유지) | D37: '테스트하다'는 붙여 씀 | F37: 테스트하기
A38: copy.safety.urgent_contacts.1.note | B38: 오류 | C38: 반영 (Claude) | D38: Claude 점검 | E38: 24시간 [확인필요] | F38: 24시간
A39: copy.worry.placeholder_examples.4 | B39: 오류 | C39: 반영 | D39: '부탁을 거절을' 목적격 조사 중복 | E39: 부탁을 거절을 못 해서 매번 손해 보는 느낌이에요. | F39: 부탁을 거절하지 못해서 매번 손해 보는 느낌이에요.
A40: emotion_lines.HUR | B40: 오류 | C40: 반영 (Claude 조정) | D40: '{name}님'과 '나에게'가 한 문장에 섞여 시점이 맞지 않음, '가장 분명한'은 단정 | E40: 지금 {name}님이 느끼는 서운함은 그 관계가 나에게 소중하다는 가장 분명한 표시예요. | F40: 지금 {name}님이 느끼는 서운함은 그 관계가 그만큼 소중하다는 표시예요.
...

Sheet 위치해석
A1: ID (수정 금지) | B1: 카드 · 분류 | C1: 항목 | D1: 현재 문장 (초안) | E1: 상태 | F1: 수정안 | G1: 검수 메모 | H1: 최종 글자 수 | I1: 분량
A2: cards.0.positions.now | B2: 00 첫 물장구 · 수달 | C2: 지금의 마음 · 정방향 | D2: 마음 한쪽에 새로 시작하고 싶은 무언가가 있어요. 아직 이름을 붙이지 못했을 수 있지만, 지금 내 안에 움직이고 싶은 에너지가 살아 있다는 뜻으로 읽을 수 있어요. | E2: 초안 | G2: [Claude 점검 · 고침] '당신' 사용 (전: 마음 한쪽에 새로 시작하고 싶은 무언가가 있어요. 아직 이름을 붙이지 못했을 수 있지만, 지금 당신 안에 움직이고 싶은 에너지가 살아 있다는 뜻으로 읽을 수 있어요.) | H2: =LEN(IF(F2<>"",F2,D2)) -> 91 | I2: =IF(OR(H2<25,H2>140),"분량 확인","")
A3: cards.0.positions.hold | B3: 00 첫 물장구 · 수달 | C3: 나를 붙잡는 것 · 정방향 | D3: '제대로 준비되면 시작해야지'라는 생각이 발목을 잡고 있을 수 있어요. 준비가 끝나는 날은 잘 오지 않아서, 기다리는 동안 시작하고 싶은 마음이 조금씩 식기도 해요. | E3: 초안 | H3: =LEN(IF(F3<>"",F3,D3)) -> 92 | I3: =IF(OR(H3<25,H3>140),"분량 확인","")
A4: cards.0.positions.step | B4: 00 첫 물장구 · 수달 | C4: 다음 한 걸음 · 정방향 | D4: 결과보다 '해 보는 것' 자체를 목표로 삼아 보세요. 수달이 물이 차가운지 발끝을 먼저 대 보듯, 아주 작게 한 번 시도해 보는 거예요. | E4: 초안 | G4: [Claude 점검 · 고침] '발끝으로 대 보듯' 어색(대다는 '을/를' 목적어) (전: 결과보다 '해 보는 것' 자체를 목표로 삼아 보세요. 수달이 물이 차가운지 발끝으로 먼저 대 보듯, 아주 작게 한 번 시도해 보는 거예요.) | H4: =LEN(IF(F4<>"",F4,D4)) -> 76 | I4: =IF(OR(H4<25,H4>140),"분량 확인","")
A5: cards.0.reversed.positions.now | B5: 00 첫 물장구 · 수달 | C5: 지금의 마음 · 역방향 | D5: 새로 시작하고 싶은 마음은 있지만, 실패할까 봐 발끝만 물에 대고 있는 상태일 수 있어요. | E5: 초안 | H5: =LEN(IF(F5<>"",F5,D5)) -> 50 | I5: =IF(OR(H5<25,H5>140),"분량 확인","")
A6: cards.0.reversed.positions.hold | B6: 00 첫 물장구 · 수달 | C6: 나를 붙잡는 것 · 역방향 | D6: '처음부터 잘해야 한다'는 기준이 첫걸음을 무겁게 만들고 있을 수 있어요. | E6: 초안 | H6: =LEN(IF(F6<>"",F6,D6)) -> 41 | I6: =IF(OR(H6<25,H6>140),"분량 확인","")
A7: cards.0.reversed.positions.step | B7: 00 첫 물장구 · 수달 | C7: 다음 한 걸음 · 역방향 | D7: 거창한 시작 대신, 물 온도만 재 보듯 오늘 아주 작은 시도 하나면 충분해요. | E7: 초안 | H7: =LEN(IF(F7<>"",F7,D7)) -> 43 | I7: =IF(OR(H7<25,H7>140),"분량 확인","")
A8: cards.1.positions.now | B8: 01 여덟 갈래의 손 · 문어 | C8: 지금의 마음 · 정방향 | D8: 해결하고 싶은 마음이 분명하고, 무엇이든 해 볼 준비가 되어 있어요. 다만 할 일이 많아 손이 여러 군데로 뻗어 있는 상태일 수 있어요. | E8: 초안 | H8: =LEN(IF(F8<>"",F8,D8)) -> 76 | I8: =IF(OR(H8<25,H8>140),"분량 확인","")
A9: cards.1.positions.hold | B9: 01 여덟 갈래의 손 · 문어 | C9: 나를 붙잡는 것 · 정방향 | D9: 없는 것에 시선이 먼저 가서, 이미 가진 강점과 도움을 놓치고 있을 수 있어요. '아직 부족하다'는 느낌이 실제보다 크게 자리 잡기 쉬워요. | E9: 초안 | H9: =LEN(IF(F9<>"",F9,D9)) -> 78 | I9: =IF(OR(H9<25,H9>140),"분량 확인","")
A10: cards.1.positions.step | B10: 01 여덟 갈래의 손 · 문어 | C10: 다음 한 걸음 · 정방향 | D10: 지금 가진 자원을 눈에 보이게 펼쳐 보세요. 시간, 사람, 경험, 작은 기술까지 적어 보면 생각보다 쓸 수 있는 손이 많다는 걸 알게 될 수 있어요. | E10: 초안 | H10: =LEN(IF(F10<>"",F10,D10)) -> 83 | I10: =IF(OR(H10<25,H10>140),"분량 확인","")
A11: cards.1.reversed.positions.now | B11: 01 여덟 갈래의 손 · 문어 | C11: 지금의 마음 · 역방향 | D11: 손이 여러 군데로 뻗어 있어 무엇 하나에도 힘이 잘 실리지 않는 느낌일 수 있어요. | E11: 초안 | H11: =LEN(IF(F11<>"",F11,D11)) -> 46 | I11: =IF(OR(H11<25,H11>140),"분량 확인","")
A12: cards.1.reversed.positions.hold | B12: 01 여덟 갈래의 손 · 문어 | C12: 나를 붙잡는 것 · 역방향 | D12: 모든 걸 다 해내야 한다는 마음이 에너지를 조각조각 나누고 있을 수 있어요. | E12: 초안 | H12: =LEN(IF(F12<>"",F12,D12)) -> 42 | I12: =IF(OR(H12<25,H12>140),"분량 확인","")
A13: cards.1.reversed.positions.step | B13: 01 여덟 갈래의 손 · 문어 | C13: 다음 한 걸음 · 역방향 | D13: 여덟 갈래의 손 중 지금 꼭 필요한 한 손만 남기고, 나머지는 잠시 내려놓아 보세요. | E13: 초안 | G13: [Claude 점검 · 고침] '여덟 갈래'와 '한 손'의 단위가 맞지 않음 (전: 여덟 갈래 중 지금 꼭 필요한 한 손만 남기고, 나머지는 잠시 내려놓아 보세요.) | H13: =LEN(IF(F13<>"",F13,D13)) -> 47 | I13: =IF(OR(H13<25,H13>140),"분량 확인","")
A14: cards.2.positions.now | B14: 02 고요히 바라보기 · 왜가리 | C14: 지금의 마음 · 정방향 | D14: 겉으로는 담담해 보여도 속으로는 많은 것을 느끼고 헤아리고 있어요. 아직 말로 정리되지 않은 감각이 마음 아래쪽에 머물러 있을 수 있어요. | E14: 초안 | H14: =LEN(IF(F14<>"",F14,D14)) -> 77 | I14: =IF(OR(H14<25,H14>140),"분량 확인","")
A15: cards.2.positions.hold | B15: 02 고요히 바라보기 · 왜가리 | C15: 나를 붙잡는 것 · 정방향 | D15: 다른 사람의 의견과 '해야 하는 것'이 커서, 내 안의 작은 목소리가 잘 들리지 않을 수 있어요. 남의 기준으로 고르면 정답처럼 보여도 마음은 개운하지 않기 쉬워요. | E15: 초안 | H15: =LEN(IF(F15<>"",F15,D15)) -> 92 | I15: =IF(OR(H15<25,H15>140),"분량 확인","")
A16: cards.2.positions.step | B16: 02 고요히 바라보기 · 왜가리 | C16: 다음 한 걸음 · 정방향 | D16: 바로 결정하지 말고 물가에 선 왜가리처럼 잠시 지켜보는 시간을 가져 보세요. 판단하지 않고 바라보면 내가 정말 원하는 것이 천천히 떠오를 수 있어요. | E16: 초안 | H16: =LEN(IF(F16<>"",F16,D16)) -> 83 | I16: =IF(OR(H16<25,H16>140),"분량 확인","")
A17: cards.2.reversed.positions.now | B17: 02 고요히 바라보기 · 왜가리 | C17: 지금의 마음 · 역방향 | D17: 생각이 너무 많아 직감이 흐려져 있거나, 느낌을 애써 외면하고 있을 수 있어요. | E17: 초안 | H17: =LEN(IF(F17<>"",F17,D17)) -> 44 | I17: =IF(OR(H17<25,H17>140),"분량 확인","")
A18: cards.2.reversed.positions.hold | B18: 02 고요히 바라보기 · 왜가리 | C18: 나를 붙잡는 것 · 역방향 | D18: 남의 의견을 계속 찾아보는 습관이 내 판단을 미루게 하고 있을 수 있어요. | E18: 초안 | H18: =LEN(IF(F18<>"",F18,D18)) -> 41 | I18: =IF(OR(H18<25,H18>140),"분량 확인","")
A19: cards.2.reversed.positions.step | B19: 02 고요히 바라보기 · 왜가리 | C19: 다음 한 걸음 · 역방향 | D19: 검색과 조언 구하기를 잠시 멈추고, 하루 10분은 아무 정보 없이 내 마음만 들어 보세요. | E19: 초안 | G19: [Claude 점검 · 고침] '조언을 멈추고'는 조언을 하는 쪽으로 읽힘 (전: 검색과 조언을 잠시 멈추고, 하루 10분은 아무 정보 없이 내 마음만 들어 보세요.) | H19: =LEN(IF(F19<>"",F19,D19)) -> 50 | I19: =IF(OR(H19<25,H19>140),"분량 확인","")
A20: cards.3.positions.now | B20: 03 품어 주는 품 · 해달 | C20: 지금의 마음 · 정방향 | D20: 누군가를 챙기고 돌보느라 마음을 많이 쓰고 있어요. 그 따뜻함은 큰 힘이지만, 정작 나를 돌볼 여유는 줄어 있을 수 있어요. | E20: 초안 | G20: [Claude 점검 · 고침] 한 문장 안에 '당신'과 '나'가 섞임(기준 예시와 동일) (전: 누군가를 챙기고 돌보느라 마음을 많이 쓰고 있어요. 그 따뜻함이 당신의 큰 힘이지만, 정작 나를 돌볼 여유는 줄어 있을 수 있어요.) | H20: =LEN(IF(F20<>"",F20,D20)) -> 69 | I20: =IF(OR(H20<25,H20>140),"분량 확인","")
A21: cards.3.positions.hold | B21: 03 품어 주는 품 · 해달 | C21: 나를 붙잡는 것 · 정방향 | D21: '나까지 챙기면 이기적인 것 같다'는 생각이 쉬어야 할 순간을 자꾸 미루게 할 수 있어요. 바닥난 채로 계속 주다 보면 다정함도 지쳐 서운함으로 바뀌기 쉬워요. | E21: 초안 | H21: =LEN(IF(F21<>"",F21,D21)) -> 89 | I21: =IF(OR(H21<25,H21>140),"분량 확인","")
A22: cards.3.positions.step | B22: 03 품어 주는 품 · 해달 | C22: 다음 한 걸음 · 정방향 | D22: 남에게 건네는 다정한 말을 나에게도 건네 보세요. 해달이 새끼를 배 위에 올려 품듯, 오늘 하루는 내 몸과 마음을 먼저 품어 주는 거예요. | E22: 초안 | H22: =LEN(IF(F22<>"",F22,D22)) -> 77 | I22: =IF(OR(H22<25,H22>140),"분량 확인","")
A23: cards.3.reversed.positions.now | B23: 03 품어 주는 품 · 해달 | C23: 지금의 마음 · 역방향 | D23: 돌봄을 주는 데 익숙해서, 받는 일이 어색하거나 미안하게 느껴질 수 있어요. | E23: 초안 | H23: =LEN(IF(F23<>"",F23,D23)) -> 42 | I23: =IF(OR(H23<25,H23>140),"분량 확인","")
A24: cards.3.reversed.positions.hold | B24: 03 품어 주는 품 · 해달 | C24: 나를 붙잡는 것 · 역방향 | D24: '내가 챙겨야 한다'는 마음이 지나쳐 스스로를 소진시키고 있을 수 있어요. | E24: 초안 | H24: =LEN(IF(F24<>"",F24,D24)) -> 41 | I24: =IF(OR(H24<25,H24>140),"분량 확인","")
A25: cards.3.reversed.positions.step | B25: 03 품어 주는 품 · 해달 | C25: 다음 한 걸음 · 역방향 | D25: 오늘은 누군가를 챙기기 전에 나에게 먼저 물 한 잔, 쉼 한 번을 건네 보세요. | E25: 초안 | H25: =LEN(IF(F25<>"",F25,D25)) -> 44 | I25: =IF(OR(H25<25,H25>140),"분량 확인","")
A26: cards.4.positions.now | B26: 04 지키는 자리 · 펭귄 | C26: 지금의 마음 · 정방향 | D26: 지켜야 할 것이 많고 책임감이 커요. 맡은 자리를 묵묵히 버티고 있는 모습이 주변 사람들에게 든든한 힘이 되고 있을지도 몰라요. | E26: 초안 | G26: [Claude 점검 · 고침] '당신' 사용, '커요'가 두 문장에서 반복, 상대 반응 단정 (전: 지켜야 할 것이 많고 책임감이 커요. 맡은 자리를 묵묵히 버티고 있는 당신은 주변 사람들에게 든든한 존재일 가능성이 커요.) | H26: =LEN(IF(F26<>"",F26,D26)) -> 71 | I26: =IF(OR(H26<25,H26>140),"분량 확인","")
A27: cards.4.positions.hold | B27: 04 지키는 자리 · 펭귄 | C27: 나를 붙잡는 것 · 정방향 | D27: 모든 걸 혼자 책임져야 한다는 생각이 어깨를 무겁게 하고 있을 수 있어요. 통제할 수 없는 것까지 붙잡으려 하면 쉬어도 쉰 것 같지 않기 쉬워요. | E27: 초안 | H27: =LEN(IF(F27<>"",F27,D27)) -> 81 | I27: =IF(OR(H27<25,H27>140),"분량 확인","")
A28: cards.4.positions.step | B28: 04 지키는 자리 · 펭귄 | C28: 다음 한 걸음 · 정방향 | D28: 내가 바꿀 수 있는 것과 바꿀 수 없는 것을 구분해 보세요. 펭귄 무리가 자리를 바꿔 가며 추위를 함께 견디듯, 바꿀 수 있는 쪽에 힘을 쓰고 나머지는 함께 나눠 지는 거예요. | E28: 초안 | G28: [Claude 점검 · 고침] '나눠 보세요'와 '나눠 지는'이 다른 뜻으로 반복되고, '바꾸-'가 네 번 나옴 (전: 내가 바꿀 수 있는 것과 바꿀 수 없는 것을 나눠 보세요. 펭귄 무리가 자리를 바꿔 가며 추위를 함께 견디듯, 바꿀 수 있는 쪽에 힘을 쓰고 나머지는 나눠 지는 거예요.) | H28: =LEN(IF(F28<>"",F28,D28)) -> 98 | I28: =IF(OR(H28<25,H28>140),"분량 확인","")
A29: cards.4.reversed.positions.now | B29: 04 지키는 자리 · 펭귄 | C29: 지금의 마음 · 역방향 | D29: 책임을 놓지 못해 긴장이 계속 이어지고 있거나, 반대로 기댈 질서가 없어 흔들리고 있을 수 있어요. | E29: 초안 | H29: =LEN(IF(F29<>"",F29,D29)) -> 55 | I29: =IF(OR(H29<25,H29>140),"분량 확인","")
A30: cards.4.reversed.positions.hold | B30: 04 지키는 자리 · 펭귄 | C30: 나를 붙잡는 것 · 역방향 | D30: 통제하려는 마음이 커질수록 작은 변화에도 쉽게 지칠 수 있어요. | E30: 초안 | H30: =LEN(IF(F30<>"",F30,D30)) -> 35 | I30: =IF(OR(H30<25,H30>140),"분량 확인","")
A31: cards.4.reversed.positions.step | B31: 04 지키는 자리 · 펭귄 | C31: 다음 한 걸음 · 역방향 | D31: 완벽한 질서 대신 하루 한 가지 작은 규칙만 지키는 데서 다시 시작해 보세요. | E31: 초안 | H31: =LEN(IF(F31<>"",F31,D31)) -> 43 | I31: =IF(OR(H31<25,H31>140),"분량 확인","")
A32: cards.5.positions.now | B32: 05 오래된 지혜 · 거북 | C32: 지금의 마음 · 정방향 | D32: 혼자서 답을 찾으려고 오래 고민해 왔을 수 있어요. 스스로 해내려는 힘이 크지만, 그만큼 생각이 같은 자리를 맴돌기도 해요. | E32: 초안 | H32: =LEN(IF(F32<>"",F32,D32)) -> 69 | I32: =IF(OR(H32<25,H32>140),"분량 확인","")
A33: cards.5.positions.hold | B33: 05 오래된 지혜 · 거북 | C33: 나를 붙잡는 것 · 정방향 | D33: '이런 걸 물어봐도 되나' 하는 망설임이 도움을 구하는 길을 막고 있을 수 있어요. 혼자 끌어안은 고민은 실제보다 무겁게 느껴지기 쉬워요. | E33: 초안 | H33: =LEN(IF(F33<>"",F33,D33)) -> 77 | I33: =IF(OR(H33<25,H33>140),"분량 확인","")
A34: cards.5.positions.step | B34: 05 오래된 지혜 · 거북 | C34: 다음 한 걸음 · 정방향 | D34: 믿을 만한 사람이나 오래 검증된 지혜에 기대어 보세요. 거북이 천천히 오래된 바닷길을 따라가듯, 같은 길을 먼저 지나간 사람의 이야기를 들어 보는 거예요. | E34: 초안 | H34: =LEN(IF(F34<>"",F34,D34)) -> 86 | I34: =IF(OR(H34<25,H34>140),"분량 확인","")
A35: cards.5.reversed.positions.now | B35: 05 오래된 지혜 · 거북 | C35: 지금의 마음 · 역방향 | D35: 혼자 해결해야 한다는 생각에 묻는 것 자체를 망설이고 있을 수 있어요. | E35: 초안 | H35: =LEN(IF(F35<>"",F35,D35)) -> 39 | I35: =IF(OR(H35<25,H35>140),"분량 확인","")
A36: cards.5.reversed.positions.hold | B36: 05 오래된 지혜 · 거북 | C36: 나를 붙잡는 것 · 역방향 | D36: '다들 하는 방식'에 나를 맞추려다 내게 맞는 답을 놓치고 있을 수 있어요. | E36: 초안 | H36: =LEN(IF(F36<>"",F36,D36)) -> 42 | I36: =IF(OR(H36<25,H36>140),"분량 확인","")
A37: cards.5.reversed.positions.step | B37: 05 오래된 지혜 · 거북 | C37: 다음 한 걸음 · 역방향 | D37: 정답을 찾기보다, 믿을 만한 한 사람에게 지금 상황을 있는 그대로 말해 보세요. | E37: 초안 | H37: =LEN(IF(F37<>"",F37,D37)) -> 44 | I37: =IF(OR(H37<25,H37>140),"분량 확인","")
A38: cards.6.positions.now | B38: 06 나란히 헤엄 · 원앙 | C38: 지금의 마음 · 정방향 | D38: 누군가와 더 가까워지고 싶거나, 중요한 선택 앞에서 마음이 오가고 있을 수 있어요. 관계와 선택 모두 나에게 그만큼 소중하다는 뜻으로 읽을 수 있어요. | E38: 초안 | G38: [Claude 점검 · 고침] '마음, 또는 ~마음이 오가고' 병렬이 어긋남, '당신' 사용 (전: 누군가와 더 가까워지고 싶은 마음, 또는 중요한 선택 앞에서 마음이 오가고 있어요. 관계와 선택 모두 당신에게 그만큼 소중하다는 뜻으로 읽을 수 있어요.) | H38: =LEN(IF(F38<>"",F38,D38)) -> 84 | I38: =IF(OR(H38<25,H38>140),"분량 확인","")
A39: cards.6.positions.hold | B39: 06 나란히 헤엄 · 원앙 | C39: 나를 붙잡는 것 · 정방향 | D39: 상대의 마음을 먼저 확인하고 싶어서 내 마음은 말하지 못하고 있을 수 있어요. 혹은 남이 보기에 좋은 선택과 내가 원하는 선택 사이에서 머뭇거리고 있을 수 있어요. | E39: 초안 | H39: =LEN(IF(F39<>"",F39,D39)) -> 91 | I39: =IF(OR(H39<25,H39>140),"분량 확인","")
A40: cards.6.positions.step | B40: 06 나란히 헤엄 · 원앙 | C40: 다음 한 걸음 · 정방향 | D40: 관계와 삶에서 내가 무엇을 소중히 여기는지 먼저 확인해 보세요. 원앙이 나란히 헤엄치듯, 가치가 같은 방향을 볼 때 연결도 선택도 한결 편안해질 수 있어요. | E40: 초안 | H40: =LEN(IF(F40<>"",F40,D40)) -> 87 | I40: =IF(OR(H40<25,H40>140),"분량 확인","")
...

Sheet 깊이읽기
A1: ID (수정 금지) | B1: 카드 · 분류 | C1: 항목 | D1: 현재 문장 (초안) | E1: 상태 | F1: 수정안 | G1: 검수 메모 | H1: 최종 글자 수 | I1: 분량
A2: cards.0.deep.now.0 | B2: 00 첫 물장구 · 수달 | C2: 지금의 마음 · 단락 1 | D2: 새로운 걸 해 보고 싶은 마음은 대개 지금의 자리가 조금 좁게 느껴질 때 찾아와요. 그 마음이 아직 흐릿하더라도, 무언가를 바꾸고 싶다는 감각은 그 자체로 내 안의 에너지가 살아 있다는 신호예요. | E2: 초안 | G2: [Claude 점검 · 고침] '그 자체로 살아 있다는 신호'에서 무엇이 살아 있는지 주어가 빠져 뜻이 모호함 (전: 새로운 걸 해 보고 싶은 마음은 대개 지금의 자리가 조금 좁게 느껴질 때 찾아와요. 그 마음이 아직 흐릿하더라도, 무언가를 바꾸고 싶다는 감각은 그 자체로 살아 있다는 신호예요.) | H2: =LEN(IF(F2<>"",F2,D2)) -> 109 | I2: =IF(OR(H2<60,H2>220),"분량 확인","")
A3: cards.0.deep.now.1 | B3: 00 첫 물장구 · 수달 | C3: 지금의 마음 · 단락 2 | D3: 요즘 나도 모르게 자꾸 눈길이 가는 것이 있다면 무엇인가요? 거창한 목표가 아니어도 괜찮아요. 그 작은 끌림에 이름을 하나 붙여 보는 것만으로도 시작은 이미 한 발 가까워져요. | E3: 초안 | H3: =LEN(IF(F3<>"",F3,D3)) -> 98 | I3: =IF(OR(H3<60,H3>220),"분량 확인","")
A4: cards.0.deep.hold.0 | B4: 00 첫 물장구 · 수달 | C4: 나를 붙잡는 것 · 단락 1 | D4: 준비를 더 하고 싶은 마음 밑에는 서툰 모습을 보이고 싶지 않은 마음이 있을 때가 많아요. 잘하고 싶은 만큼 첫 시도의 어색함이 크게 느껴지는 건 자연스러운 일이에요. | E4: 초안 | H4: =LEN(IF(F4<>"",F4,D4)) -> 93 | I4: =IF(OR(H4<60,H4>220),"분량 확인","")
A5: cards.0.deep.hold.1 | B5: 00 첫 물장구 · 수달 | C5: 나를 붙잡는 것 · 단락 2 | D5: 지금 기다리고 있는 '준비 완료'의 기준이 무엇인지 한번 적어 보세요. 적어 놓고 보면 그중 몇 가지는 시작한 뒤에야 채울 수 있는 것들이라는 걸 발견하게 될 수도 있어요. | E5: 초안 | H5: =LEN(IF(F5<>"",F5,D5)) -> 96 | I5: =IF(OR(H5<60,H5>220),"분량 확인","")
A6: cards.0.deep.step.0 | B6: 00 첫 물장구 · 수달 | C6: 다음 한 걸음 · 단락 1 | D6: 첫걸음이 작을수록 실패의 무게도 가벼워져요. 결과를 정해 두지 않고 '해 봤다'는 경험을 목표로 삼으면, 다음에 무엇을 할지는 해 보는 과정에서 조금씩 보이기 시작해요. | E6: 초안 | H6: =LEN(IF(F6<>"",F6,D6)) -> 94 | I6: =IF(OR(H6<60,H6>220),"분량 확인","")
A7: cards.0.deep.step.1 | B7: 00 첫 물장구 · 수달 | C7: 다음 한 걸음 · 단락 2 | D7: 오늘 할 수 있는 가장 작은 버전은 무엇일까요? 검색 한 번, 문의 한 통, 10분 연습처럼 물 온도를 재 보는 정도의 크기면 충분해요. 해 본 뒤의 느낌을 짧게 남겨 두면 다음 물장구가 한결 쉬워져요. | E7: 초안 | H7: =LEN(IF(F7<>"",F7,D7)) -> 113 | I7: =IF(OR(H7<60,H7>220),"분량 확인","")
A8: cards.1.deep.now.0 | B8: 01 여덟 갈래의 손 · 문어 | C8: 지금의 마음 · 단락 1 | D8: 해내고 싶은 마음이 크면 손이 저절로 여러 곳으로 뻗어요. 지금의 분주함은 그만큼 많은 걸 책임지고 싶은 성실함에서 나온 것일 수 있어요. | E8: 초안 | G8: [Claude 점검 · 고침] '당신의 성실함' - 보고서는 '당신' 대신 주어 생략 권장 (전: 해내고 싶은 마음이 크면 손이 저절로 여러 곳으로 뻗어요. 지금의 분주함은 그만큼 많은 걸 책임지고 싶은 당신의 성실함에서 나온 것일 수 있어요.) | H8: =LEN(IF(F8<>"",F8,D8)) -> 77 | I8: =IF(OR(H8<60,H8>220),"분량 확인","")
A9: cards.1.deep.now.1 | B9: 01 여덟 갈래의 손 · 문어 | C9: 지금의 마음 · 단락 2 | D9: 지금 손을 뻗고 있는 곳들 가운데 정말 내가 쥐고 싶은 것은 무엇인가요? 모든 손에 같은 힘을 줄 필요는 없어요. 가장 마음이 가는 한두 곳을 먼저 골라 보면 분주함 속에서도 중심이 생겨요. | E9: 초안 | G9: [Claude 점검 · 고침] '뻗어 있는 손들 가운데 내가 쥐고 싶은 것' - 손이 쥘 대상인 것처럼 읽혀 논리가 어긋남 (전: 지금 뻗어 있는 손들 가운데 정말 내가 쥐고 싶은 것은 무엇인가요? 모든 손에 같은 힘을 줄 필요는 없어요. 가장 마음이 가는 한두 곳을 먼저 골라 보면 분주함 속에서도 중심이 생겨요.) | H9: =LEN(IF(F9<>"",F9,D9)) -> 106 | I9: =IF(OR(H9<60,H9>220),"분량 확인","")
A10: cards.1.deep.hold.0 | B10: 01 여덟 갈래의 손 · 문어 | C10: 나를 붙잡는 것 · 단락 1 | D10: 부족한 점이 먼저 눈에 들어오는 건 더 잘하고 싶은 마음이 크기 때문이기도 해요. 다만 그 시선이 오래 머물면, 이미 해 온 일과 곁에 있는 도움이 배경처럼 흐려지기 쉬워요. | E10: 초안 | H10: =LEN(IF(F10<>"",F10,D10)) -> 97 | I10: =IF(OR(H10<60,H10>220),"분량 확인","")
A11: cards.1.deep.hold.1 | B11: 01 여덟 갈래의 손 · 문어 | C11: 나를 붙잡는 것 · 단락 2 | D11: 최근에 '이건 내가 꽤 잘했다' 싶었던 순간을 하나 떠올려 보세요. 그때 쓴 힘은 지금의 고민에도 그대로 쓸 수 있는 힘이에요. 없는 것의 목록 옆에 있는 것의 목록도 나란히 적어 보세요. | E11: 초안 | H11: =LEN(IF(F11<>"",F11,D11)) -> 105 | I11: =IF(OR(H11<60,H11>220),"분량 확인","")
A12: cards.1.deep.step.0 | B12: 01 여덟 갈래의 손 · 문어 | C12: 다음 한 걸음 · 단락 1 | D12: 자원을 눈에 보이게 펼쳐 두면 막연하던 고민이 '이걸로 무엇을 해 볼까'라는 질문으로 바뀌어요. 문어가 여덟 갈래의 손을 각각 다르게 쓰듯, 가진 것마다 맡길 수 있는 역할이 달라요. | E12: 초안 | H12: =LEN(IF(F12<>"",F12,D12)) -> 102 | I12: =IF(OR(H12<60,H12>220),"분량 확인","")
A13: cards.1.deep.step.1 | B13: 01 여덟 갈래의 손 · 문어 | C13: 다음 한 걸음 · 단락 2 | D13: 시간, 사람, 경험, 작은 기술을 네 칸으로 나눠 적어 보세요. 그중 이번 주에 바로 꺼내 쓸 수 있는 것 하나를 골라 고민에 연결해 보면, 해결이 생각보다 가까이 있다는 감각이 생길 수 있어요. | E13: 초안 | H13: =LEN(IF(F13<>"",F13,D13)) -> 109 | I13: =IF(OR(H13<60,H13>220),"분량 확인","")
A14: cards.2.deep.now.0 | B14: 02 고요히 바라보기 · 왜가리 | C14: 지금의 마음 · 단락 1 | D14: 말로 꺼내기 전의 감각은 대개 조용하고 느리게 움직여요. 겉으로는 담담해 보여도 속에서 많은 것을 헤아리고 있다는 건, 그만큼 이 고민을 섬세하게 다루고 있다는 뜻이에요. | E14: 초안 | H14: =LEN(IF(F14<>"",F14,D14)) -> 95 | I14: =IF(OR(H14<60,H14>220),"분량 확인","")
A15: cards.2.deep.now.1 | B15: 02 고요히 바라보기 · 왜가리 | C15: 지금의 마음 · 단락 2 | D15: 지금 마음 아래에 머물러 있는 느낌을 한 단어로 불러 본다면 무엇일까요? 정확하지 않아도 괜찮아요. 떠오르는 대로 불러 보면 그 감각이 조금씩 모양을 갖추기 시작해요. | E15: 초안 | H15: =LEN(IF(F15<>"",F15,D15)) -> 93 | I15: =IF(OR(H15<60,H15>220),"분량 확인","")
A16: cards.2.deep.hold.0 | B16: 02 고요히 바라보기 · 왜가리 | C16: 나를 붙잡는 것 · 단락 1 | D16: 다른 사람의 의견이나 '해야 하는 것'은 소리가 크고 분명해서 쉽게 들려요. 반면 내 안의 목소리는 작고 머뭇거릴 때가 많아서, 바쁜 날에는 그 소리를 놓치기 쉬워요. | E16: 초안 | G16: [Claude 점검 · 고침] '목소리는 작고 망설이는 모양이라' - 목소리에 '모양'이 어울리지 않음 (전: 다른 사람의 의견이나 '해야 하는 것'은 소리가 크고 분명해서 쉽게 들려요. 반면 내 안의 목소리는 작고 망설이는 모양이라, 바쁜 날에는 그 소리를 놓치기 쉬워요.) | H16: =LEN(IF(F16<>"",F16,D16)) -> 93 | I16: =IF(OR(H16<60,H16>220),"분량 확인","")
A17: cards.2.deep.hold.1 | B17: 02 고요히 바라보기 · 왜가리 | C17: 나를 붙잡는 것 · 단락 2 | D17: 누군가의 기대를 잠시 내려놓고 '아무도 평가하지 않는다면 나는 무엇을 고를까?' 하고 물어보세요. 바로 답하지 않아도 괜찮아요. 질문을 품고 하루를 보내면 마음이 기우는 쪽이 은근히 드러나요. | E17: 초안 | H17: =LEN(IF(F17<>"",F17,D17)) -> 107 | I17: =IF(OR(H17<60,H17>220),"분량 확인","")
A18: cards.2.deep.step.0 | B18: 02 고요히 바라보기 · 왜가리 | C18: 다음 한 걸음 · 단락 1 | D18: 판단을 잠시 미루는 건 결정을 피하는 것과 달라요. 충분히 바라본 뒤의 선택은 덜 흔들리고, 고른 뒤에도 나를 덜 탓하게 해 줘요. | E18: 초안 | H18: =LEN(IF(F18<>"",F18,D18)) -> 73 | I18: =IF(OR(H18<60,H18>220),"분량 확인","")
A19: cards.2.deep.step.1 | B19: 02 고요히 바라보기 · 왜가리 | C19: 다음 한 걸음 · 단락 2 | D19: 오늘은 결론을 내리지 않기로 정하고, 고민이 떠오를 때마다 드는 느낌만 짧게 적어 보세요. 며칠 모아 읽어 보면 반복해서 나오는 마음이 보이고, 그게 내가 원하는 방향의 실마리가 될 수 있어요. | E19: 초안 | H19: =LEN(IF(F19<>"",F19,D19)) -> 108 | I19: =IF(OR(H19<60,H19>220),"분량 확인","")
A20: cards.3.deep.now.0 | B20: 03 품어 주는 품 · 해달 | C20: 지금의 마음 · 단락 1 | D20: 누군가를 돌보는 일은 마음을 꽤 많이 쓰는 일이에요. 그 따뜻함은 큰 힘이지만, 쓴 만큼 채워지지 않으면 어느새 내 쪽 그릇이 비어 가기도 해요. | E20: 초안 | G20: [Claude 점검 · 고침] 한 문장 안에서 '당신이 가진 큰 힘'과 '내 쪽 그릇'이 섞임(BRIEF의 예시와 같은 유형). 위치해석 문장('그 따뜻함이 당신의 큰 힘이지만')도 거의 그대로 반복 (전: 누군가를 돌보는 일은 마음을 꽤 많이 쓰는 일이에요. 그 따뜻함은 당신이 가진 큰 힘이지만, 쓴 만큼 채워지지 않으면 어느새 내 쪽 그릇이 비어 가기도 해요.) | H20: =LEN(IF(F20<>"",F20,D20)) -> 81 | I20: =IF(OR(H20<60,H20>220),"분량 확인","")
A21: cards.3.deep.now.1 | B21: 03 품어 주는 품 · 해달 | C21: 지금의 마음 · 단락 2 | D21: 요즘 나를 위해 쓴 시간은 하루에 얼마나 되나요? 숫자로 떠올려 보면 생각보다 적을 수 있어요. 그 시간을 조금 늘리는 건 돌봄을 줄이는 게 아니라, 오래 돌볼 수 있게 나를 채우는 일이에요. | E21: 초안 | H21: =LEN(IF(F21<>"",F21,D21)) -> 107 | I21: =IF(OR(H21<60,H21>220),"분량 확인","")
A22: cards.3.deep.hold.0 | B22: 03 품어 주는 품 · 해달 | C22: 나를 붙잡는 것 · 단락 1 | D22: 나를 챙기는 게 이기적으로 느껴진다면, 오랫동안 남을 먼저 생각하는 쪽이 익숙했기 때문일 수 있어요. 그 습관은 다정함에서 시작됐지만, 지친 상태에선 그 다정함마저 무겁게 느껴질 수 있어요. | E22: 초안 | H22: =LEN(IF(F22<>"",F22,D22)) -> 106 | I22: =IF(OR(H22<60,H22>220),"분량 확인","")
A23: cards.3.deep.hold.1 | B23: 03 품어 주는 품 · 해달 | C23: 나를 붙잡는 것 · 단락 2 | D23: 소중한 사람이 지금의 나처럼 지쳐 있다면 뭐라고 말해 줄까요? 그 말을 그대로 나에게 돌려줘 보세요. 남에게는 당연한 쉼을 나에게도 똑같이 조금씩 허락해 보는 거예요. | E23: 초안 | G23: [Claude 점검 · 고침] '당연하다는 걸 허락해 보는 거예요' - 사실(~라는 것)을 허락한다는 어색한 연결 (전: 소중한 사람이 지금의 나처럼 지쳐 있다면 뭐라고 말해 줄까요? 그 말을 그대로 나에게 돌려줘 보세요. 남에게는 당연한 쉼이 나에게도 똑같이 당연하다는 걸 조금씩 허락해 보는 거예요.) | H23: =LEN(IF(F23<>"",F23,D23)) -> 93 | I23: =IF(OR(H23<60,H23>220),"분량 확인","")
A24: cards.3.deep.step.0 | B24: 03 품어 주는 품 · 해달 | C24: 다음 한 걸음 · 단락 1 | D24: 나를 품어 주는 일은 거창하지 않아도 돼요. 따뜻한 음료 한 잔, 일찍 눕는 저녁, 나에게 건네는 다정한 말 한마디처럼 몸과 마음이 '돌봄을 받았다'고 느끼는 순간이면 충분해요. | E24: 초안 | H24: =LEN(IF(F24<>"",F24,D24)) -> 99 | I24: =IF(OR(H24<60,H24>220),"분량 확인","")
A25: cards.3.deep.step.1 | B25: 03 품어 주는 품 · 해달 | C25: 다음 한 걸음 · 단락 2 | D25: 오늘 나를 위해 해 줄 수 있는 돌봄 하나를 미리 정해 두세요. 그리고 그 시간만큼은 다른 사람을 챙기는 생각을 잠시 내려놓아 보세요. 채워진 품이어야 다시 누군가를 넉넉히 안을 수 있어요. | E25: 초안 | H25: =LEN(IF(F25<>"",F25,D25)) -> 106 | I25: =IF(OR(H25<60,H25>220),"분량 확인","")
A26: cards.4.deep.now.0 | B26: 04 지키는 자리 · 펭귄 | C26: 지금의 마음 · 단락 1 | D26: 책임감이 큰 사람은 흔들리는 상황에서도 자리를 지키는 쪽을 택해요. 그 묵묵함 덕분에 주변이 안정을 얻기도 하지만, 그만큼 내 어깨에도 무게가 실려 있어요. | E26: 초안 | G26: [Claude 점검 · 고침] '당신의 어깨' 호칭, '가능성이 커요'가 위치해석('든든한 존재일 가능성이 커요')과 겹침 (전: 책임감이 큰 사람은 흔들리는 상황에서도 자리를 지키는 쪽을 택해요. 그 묵묵함 덕분에 주변이 안정을 얻고 있을 가능성이 커요. 그만큼 당신의 어깨에도 무게가 실려 있어요.) | H26: =LEN(IF(F26<>"",F26,D26)) -> 87 | I26: =IF(OR(H26<60,H26>220),"분량 확인","")
A27: cards.4.deep.now.1 | B27: 04 지키는 자리 · 펭귄 | C27: 지금의 마음 · 단락 2 | D27: 지금 지키고 있는 것들을 하나씩 떠올려 보세요. 그 목록 안에 '나 자신'도 들어 있나요? 지키는 사람도 지켜질 필요가 있다는 걸 오늘은 잠깐 기억해 주세요. | E27: 초안 | H27: =LEN(IF(F27<>"",F27,D27)) -> 88 | I27: =IF(OR(H27<60,H27>220),"분량 확인","")
A28: cards.4.deep.hold.0 | B28: 04 지키는 자리 · 펭귄 | C28: 나를 붙잡는 것 · 단락 1 | D28: 모든 걸 붙잡으려는 마음은 '내가 놓으면 무너질 것 같다'는 걱정에서 시작될 때가 많아요. 하지만 통제할 수 없는 것까지 쥐고 있으면, 정작 바꿀 수 있는 일에 쓸 힘이 남지 않아요. | E28: 초안 | H28: =LEN(IF(F28<>"",F28,D28)) -> 102 | I28: =IF(OR(H28<60,H28>220),"분량 확인","")
A29: cards.4.deep.hold.1 | B29: 04 지키는 자리 · 펭귄 | C29: 나를 붙잡는 것 · 단락 2 | D29: 요즘 마음을 쓰고 있는 일들을 '내가 바꿀 수 있는 것'과 '내 손 밖의 것'으로 나눠 보세요. 손 밖의 것을 내려놓는다고 책임을 버리는 건 아니에요. 오히려 힘을 써야 할 곳이 선명해져요. | E29: 초안 | H29: =LEN(IF(F29<>"",F29,D29)) -> 106 | I29: =IF(OR(H29<60,H29>220),"분량 확인","")
A30: cards.4.deep.step.0 | B30: 04 지키는 자리 · 펭귄 | C30: 다음 한 걸음 · 단락 1 | D30: 작은 질서는 흔들리는 날의 발판이 돼요. 정해진 시간에 하는 정리, 하루의 끝을 표시하는 습관처럼 예측할 수 있는 무언가가 있으면 마음이 기댈 곳이 생겨요. | E30: 초안 | H30: =LEN(IF(F30<>"",F30,D30)) -> 87 | I30: =IF(OR(H30<60,H30>220),"분량 확인","")
A31: cards.4.deep.step.1 | B31: 04 지키는 자리 · 펭귄 | C31: 다음 한 걸음 · 단락 2 | D31: 혼자 지던 무게 중 나눌 수 있는 것이 있다면 무엇일까요? 부탁 하나, 위임 하나, 미뤄도 되는 일 하나를 골라 보세요. 펭귄 무리처럼 자리를 바꿔 가며 견디면 추위도 덜 매섭게 느껴져요. | E31: 초안 | H31: =LEN(IF(F31<>"",F31,D31)) -> 105 | I31: =IF(OR(H31<60,H31>220),"분량 확인","")
A32: cards.5.deep.now.0 | B32: 05 오래된 지혜 · 거북 | C32: 지금의 마음 · 단락 1 | D32: 스스로 답을 찾으려는 힘은 큰 장점이에요. 다만 같은 질문을 혼자 오래 붙잡고 있으면, 생각이 새 길을 찾기보다 익숙한 길을 다시 걷게 되기 쉬워요. | E32: 초안 | G32: [Claude 점검 · 고침] '당신이 가진 큰 장점' - '당신' 호칭 (전: 스스로 답을 찾으려는 힘은 당신이 가진 큰 장점이에요. 다만 같은 질문을 혼자 오래 붙잡고 있으면, 생각이 새 길을 찾기보다 익숙한 길을 다시 걷게 되기 쉬워요.) | H32: =LEN(IF(F32<>"",F32,D32)) -> 83 | I32: =IF(OR(H32<60,H32>220),"분량 확인","")
A33: cards.5.deep.now.1 | B33: 05 오래된 지혜 · 거북 | C33: 지금의 마음 · 단락 2 | D33: 이 고민을 처음 품었을 때와 지금, 생각이 얼마나 달라졌나요? 크게 달라지지 않았다면, 이제는 바깥의 시선을 조금 빌릴 때일 수 있어요. 혼자 쌓아 온 고민은 누군가와 나눌 때 새로운 결이 생겨요. | E33: 초안 | H33: =LEN(IF(F33<>"",F33,D33)) -> 110 | I33: =IF(OR(H33<60,H33>220),"분량 확인","")
A34: cards.5.deep.hold.0 | B34: 05 오래된 지혜 · 거북 | C34: 나를 붙잡는 것 · 단락 1 | D34: 도움을 청하기 어려운 건 상대에게 부담이 될까 봐, 혹은 '이 정도는 혼자 해야지' 하는 마음 때문일 때가 많아요. 그 배려와 책임감이 오히려 나를 고립시키고 있을 수도 있어요. | E34: 초안 | H34: =LEN(IF(F34<>"",F34,D34)) -> 99 | I34: =IF(OR(H34<60,H34>220),"분량 확인","")
A35: cards.5.deep.hold.1 | B35: 05 오래된 지혜 · 거북 | C35: 나를 붙잡는 것 · 단락 2 | D35: 내가 누군가의 고민을 들었을 때 부담스러웠던 적이 많았나요? 오히려 믿고 말해 줘서 고마웠던 기억이 더 많을지도 몰라요. 묻는 일은 약함이 아니라, 관계를 믿는 방식이기도 해요. | E35: 초안 | H35: =LEN(IF(F35<>"",F35,D35)) -> 99 | I35: =IF(OR(H35<60,H35>220),"분량 확인","")
A36: cards.5.deep.step.0 | B36: 05 오래된 지혜 · 거북 | C36: 다음 한 걸음 · 단락 1 | D36: 오래 검증된 지혜는 책 한 권일 수도, 경험 많은 선배의 한마디일 수도, 전문가의 도움일 수도 있어요. 먼저 그 길을 걸어 본 사람의 이야기에는 내가 아직 보지 못한 지도가 담겨 있을 수 있어요. | E36: 초안 | G36: [Claude 점검 · 고침] '같은 길을 먼저 지나간 사람의 이야기'가 위치해석 문장을 그대로 반복하고, '지도가 담겨 있어요'는 단정 (전: 오래 검증된 지혜는 책 한 권일 수도, 경험 많은 선배의 한마디일 수도, 전문가의 도움일 수도 있어요. 같은 길을 먼저 지나간 사람의 이야기에는 내가 아직 보지 못한 지도가 담겨 있어요.) | H36: =LEN(IF(F36<>"",F36,D36)) -> 109 | I36: =IF(OR(H36<60,H36>220),"분량 확인","")
A37: cards.5.deep.step.1 | B37: 05 오래된 지혜 · 거북 | C37: 다음 한 걸음 · 단락 2 | D37: 이 고민에 대해 이야기를 들어 보고 싶은 사람이나 자료를 하나 떠올려 보세요. 거북이 천천히 가듯 서두를 필요는 없어요. 묻고 싶은 질문 하나를 미리 적어 두는 것부터 시작해도 충분해요. | E37: 초안 | H37: =LEN(IF(F37<>"",F37,D37)) -> 104 | I37: =IF(OR(H37<60,H37>220),"분량 확인","")
A38: cards.6.deep.now.0 | B38: 06 나란히 헤엄 · 원앙 | C38: 지금의 마음 · 단락 1 | D38: 가까워지고 싶은 마음과 선택 앞의 망설임은 모두 무언가가 나에게 중요하다는 데서 나와요. 마음이 오가는 건 우유부단해서가 아니라, 그만큼 신중하게 아끼고 있다는 뜻이에요. | E38: 초안 | H38: =LEN(IF(F38<>"",F38,D38)) -> 95 | I38: =IF(OR(H38<60,H38>220),"분량 확인","")
A39: cards.6.deep.now.1 | B39: 06 나란히 헤엄 · 원앙 | C39: 지금의 마음 · 단락 2 | D39: 이 관계나 선택에서 내가 가장 지키고 싶은 것은 무엇인가요? 편안함, 존중, 성장, 함께하는 시간처럼 한두 단어로 적어 보세요. 그 단어가 앞으로 마음을 정할 때 기준이 되어 줄 수 있어요. | E39: 초안 | G39: [Claude 점검 · 고침] '앞으로의 마음을 고르는 기준' - 마음을 고른다는 표현이 어색함 (전: 이 관계나 선택에서 내가 가장 지키고 싶은 것은 무엇인가요? 편안함, 존중, 성장, 함께하는 시간처럼 한두 단어로 적어 보세요. 그 단어가 앞으로의 마음을 고르는 기준이 되어 줄 수 있어요.) | H39: =LEN(IF(F39<>"",F39,D39)) -> 106 | I39: =IF(OR(H39<60,H39>220),"분량 확인","")
A40: cards.6.deep.hold.0 | B40: 06 나란히 헤엄 · 원앙 | C40: 나를 붙잡는 것 · 단락 1 | D40: 상대의 마음을 먼저 확인하고 싶은 건 상처받고 싶지 않은 마음에서 비롯될 때가 많아요. 또 남이 보기에 좋은 선택을 따르면 적어도 탓을 덜 들을 것 같아 안전하게 느껴지기도 해요. | E40: 초안 | G40: [Claude 점검 · 고침] '탓을 덜 받을' - 관용 표현은 '탓을 듣다' (전: 상대의 마음을 먼저 확인하고 싶은 건 상처받고 싶지 않은 마음에서 비롯될 때가 많아요. 또 남이 보기에 좋은 선택을 따르면 적어도 탓을 덜 받을 것 같아 안전하게 느껴지기도 해요.) | H40: =LEN(IF(F40<>"",F40,D40)) -> 100 | I40: =IF(OR(H40<60,H40>220),"분량 확인","")
...

Sheet 핵심메시지
A1: ID (수정 금지) | B1: 카드 · 분류 | C1: 항목 | D1: 현재 문장 (초안) | E1: 상태 | F1: 수정안 | G1: 검수 메모 | H1: 최종 글자 수 | I1: 분량
A2: cards.0.core | B2: 00 첫 물장구 · 수달 | C2: 핵심 메시지 · 정방향 | D2: 완벽하게 준비되지 않아도 첫 물장구는 칠 수 있어요. | E2: 초안 | H2: =LEN(IF(F2<>"",F2,D2)) -> 29 | I2: =IF(OR(H2<12,H2>60),"분량 확인","")
A3: cards.0.reversed.core | B3: 00 첫 물장구 · 수달 | C3: 핵심 메시지 · 역방향 | D3: 시작하고 싶은 마음이 아직 물가에서 망설이고 있어요. | E3: 초안 | H3: =LEN(IF(F3<>"",F3,D3)) -> 29 | I3: =IF(OR(H3<12,H3>60),"분량 확인","")
A4: cards.1.core | B4: 01 여덟 갈래의 손 · 문어 | C4: 핵심 메시지 · 정방향 | D4: 필요한 것은 이미 내 손 안에 꽤 많이 있어요. | E4: 초안 | G4: [Claude 점검 · 고침] '당신' 사용 (전: 필요한 것은 이미 당신 손 안에 꽤 많이 있어요.) | H4: =LEN(IF(F4<>"",F4,D4)) -> 26 | I4: =IF(OR(H4<12,H4>60),"분량 확인","")
A5: cards.1.reversed.core | B5: 01 여덟 갈래의 손 · 문어 | C5: 핵심 메시지 · 역방향 | D5: 가진 힘이 여기저기 흩어져 제자리를 찾지 못하고 있어요. | E5: 초안 | H5: =LEN(IF(F5<>"",F5,D5)) -> 31 | I5: =IF(OR(H5<12,H5>60),"분량 확인","")
A6: cards.2.core | B6: 02 고요히 바라보기 · 왜가리 | C6: 핵심 메시지 · 정방향 | D6: 답은 조용해질 때 비로소 들리기도 해요. | E6: 초안 | H6: =LEN(IF(F6<>"",F6,D6)) -> 22 | I6: =IF(OR(H6<12,H6>60),"분량 확인","")
A7: cards.2.reversed.core | B7: 02 고요히 바라보기 · 왜가리 | C7: 핵심 메시지 · 역방향 | D7: 내 안의 목소리가 소음에 묻혀 잘 들리지 않아요. | E7: 초안 | H7: =LEN(IF(F7<>"",F7,D7)) -> 27 | I7: =IF(OR(H7<12,H7>60),"분량 확인","")
A8: cards.3.core | B8: 03 품어 주는 품 · 해달 | C8: 핵심 메시지 · 정방향 | D8: 다른 이를 품듯, 이제 나를 품어 줄 차례예요. | E8: 초안 | H8: =LEN(IF(F8<>"",F8,D8)) -> 26 | I8: =IF(OR(H8<12,H8>60),"분량 확인","")
A9: cards.3.reversed.core | B9: 03 품어 주는 품 · 해달 | C9: 핵심 메시지 · 역방향 | D9: 남을 품느라 정작 나는 비어 있어요. | E9: 초안 | H9: =LEN(IF(F9<>"",F9,D9)) -> 20 | I9: =IF(OR(H9<12,H9>60),"분량 확인","")
A10: cards.4.core | B10: 04 지키는 자리 · 펭귄 | C10: 핵심 메시지 · 정방향 | D10: 흔들릴수록 작은 질서 하나가 나를 지켜 줘요. | E10: 초안 | H10: =LEN(IF(F10<>"",F10,D10)) -> 25 | I10: =IF(OR(H10<12,H10>60),"분량 확인","")
A11: cards.4.reversed.core | B11: 04 지키는 자리 · 펭귄 | C11: 핵심 메시지 · 역방향 | D11: 지키려는 힘이 너무 단단해져 나를 가두고 있어요. | E11: 초안 | H11: =LEN(IF(F11<>"",F11,D11)) -> 27 | I11: =IF(OR(H11<12,H11>60),"분량 확인","")
A12: cards.5.core | B12: 05 오래된 지혜 · 거북 | C12: 핵심 메시지 · 정방향 | D12: 혼자 답을 찾지 않아도 돼요. 먼저 걸어간 이들의 지혜가 있어요. | E12: 초안 | H12: =LEN(IF(F12<>"",F12,D12)) -> 36 | I12: =IF(OR(H12<12,H12>60),"분량 확인","")
A13: cards.5.reversed.core | B13: 05 오래된 지혜 · 거북 | C13: 핵심 메시지 · 역방향 | D13: 도움을 구하는 문을 아직 두드리지 못하고 있어요. | E13: 초안 | G13: [Claude 점검 · 고침] '도움을 구하는 길이 닫혀 있어요'는 위기 상황에서 절망적으로 읽힘 (전: 도움을 구하는 길이 아직 닫혀 있어요.) | H13: =LEN(IF(F13<>"",F13,D13)) -> 27 | I13: =IF(OR(H13<12,H13>60),"분량 확인","")
A14: cards.6.core | B14: 06 나란히 헤엄 · 원앙 | C14: 핵심 메시지 · 정방향 | D14: 마음이 원하는 연결은 나다운 선택에서 시작돼요. | E14: 초안 | H14: =LEN(IF(F14<>"",F14,D14)) -> 26 | I14: =IF(OR(H14<12,H14>60),"분량 확인","")
A15: cards.6.reversed.core | B15: 06 나란히 헤엄 · 원앙 | C15: 핵심 메시지 · 역방향 | D15: 연결과 선택 사이에서 마음이 엇갈려 있어요. | E15: 초안 | H15: =LEN(IF(F15<>"",F15,D15)) -> 24 | I15: =IF(OR(H15<12,H15>60),"분량 확인","")
A16: cards.7.core | B16: 07 파도를 타는 힘 · 돌고래 | C16: 핵심 메시지 · 정방향 | D16: 힘껏 거스르기보다 파도를 타고 나아가요. | E16: 초안 | H16: =LEN(IF(F16<>"",F16,D16)) -> 22 | I16: =IF(OR(H16<12,H16>60),"분량 확인","")
A17: cards.7.reversed.core | B17: 07 파도를 타는 힘 · 돌고래 | C17: 핵심 메시지 · 역방향 | D17: 나아가려는 힘이 방향을 잃고 맴돌고 있어요. | E17: 초안 | H17: =LEN(IF(F17<>"",F17,D17)) -> 24 | I17: =IF(OR(H17<12,H17>60),"분량 확인","")
A18: cards.8.core | B18: 08 진주를 품는 힘 · 조개 | C18: 핵심 메시지 · 정방향 | D18: 불편한 감정을 품어 주는 시간이 단단함을 만들어요. | E18: 초안 | G18: [Claude 점검 · 고침] '불편함을 품는 시간'이 상황(폭력 등)을 참으라는 뜻으로 읽힐 수 있음 (전: 불편함을 품는 시간이 단단함을 만들어요.) | H18: =LEN(IF(F18<>"",F18,D18)) -> 28 | I18: =IF(OR(H18<12,H18>60),"분량 확인","")
A19: cards.8.reversed.core | B19: 08 진주를 품는 힘 · 조개 | C19: 핵심 메시지 · 역방향 | D19: 불편함을 너무 오래 혼자 품고 있어요. | E19: 초안 | H19: =LEN(IF(F19<>"",F19,D19)) -> 21 | I19: =IF(OR(H19<12,H19>60),"분량 확인","")
A20: cards.9.core | B20: 09 나만의 등불 · 바다의 노인 | C20: 핵심 메시지 · 정방향 | D20: 혼자 있는 시간은 나를 비추는 등불이 될 수 있어요. | E20: 초안 | H20: =LEN(IF(F20<>"",F20,D20)) -> 29 | I20: =IF(OR(H20<12,H20>60),"분량 확인","")
A21: cards.9.reversed.core | B21: 09 나만의 등불 · 바다의 노인 | C21: 핵심 메시지 · 역방향 | D21: 혼자만의 시간이 쉼이 아니라 고립이 되어 가고 있어요. | E21: 초안 | H21: =LEN(IF(F21<>"",F21,D21)) -> 30 | I21: =IF(OR(H21<12,H21>60),"분량 확인","")
A22: cards.10.core | B22: 10 물살의 순환 · 가오리 | C22: 핵심 메시지 · 정방향 | D22: 지금의 물살도 지나가요. 흐름은 돌고 돌아요. | E22: 초안 | H22: =LEN(IF(F22<>"",F22,D22)) -> 25 | I22: =IF(OR(H22<12,H22>60),"분량 확인","")
A23: cards.10.reversed.core | B23: 10 물살의 순환 · 가오리 | C23: 핵심 메시지 · 역방향 | D23: 변화의 흐름에 맞서느라 힘이 잔뜩 들어가 있어요. | E23: 초안 | H23: =LEN(IF(F23<>"",F23,D23)) -> 27 | I23: =IF(OR(H23<12,H23>60),"분량 확인","")
A24: cards.11.core | B24: 11 고요한 균형 · 백조 | C24: 핵심 메시지 · 정방향 | D24: 나에게도 공정한 저울을 내밀어 보세요. | E24: 초안 | H24: =LEN(IF(F24<>"",F24,D24)) -> 21 | I24: =IF(OR(H24<12,H24>60),"분량 확인","")
A25: cards.11.reversed.core | B25: 11 고요한 균형 · 백조 | C25: 핵심 메시지 · 역방향 | D25: 저울이 한쪽으로 기울어 있어요. | E25: 초안 | H25: =LEN(IF(F25<>"",F25,D25)) -> 17 | I25: =IF(OR(H25<12,H25>60),"분량 확인","")
A26: cards.12.core | B26: 12 바위 위의 쉼 · 물범 | C26: 핵심 메시지 · 정방향 | D26: 멈춤은 뒤처짐이 아니라 다르게 보기 위한 시간이에요. | E26: 초안 | H26: =LEN(IF(F26<>"",F26,D26)) -> 29 | I26: =IF(OR(H26<12,H26>60),"분량 확인","")
A27: cards.12.reversed.core | B27: 12 바위 위의 쉼 · 물범 | C27: 핵심 메시지 · 역방향 | D27: 멈춰 있는 시간이 쉼이 아니라 정체처럼 느껴져요. | E27: 초안 | H27: =LEN(IF(F27<>"",F27,D27)) -> 27 | I27: =IF(OR(H27<12,H27>60),"분량 확인","")
A28: cards.13.core | B28: 13 새 집으로 이사 · 소라게 | C28: 핵심 메시지 · 정방향 | D28: 맞지 않는 껍데기를 내려놓을 때 새 집으로 옮겨 갈 수 있어요. | E28: 초안 | G28: [Claude 점검 · 고침] '-아야 들어갈 수 있어요'가 지금 관계·직장을 떠나야 한다는 단정으로 읽힐 수 있음 (전: 맞지 않는 껍데기를 내려놓아야 새 집에 들어갈 수 있어요.) | H28: =LEN(IF(F28<>"",F28,D28)) -> 35 | I28: =IF(OR(H28<12,H28>60),"분량 확인","")
A29: cards.13.reversed.core | B29: 13 새 집으로 이사 · 소라게 | C29: 핵심 메시지 · 역방향 | D29: 내려놓을 것을 아직 놓지 못하고 있어요. | E29: 초안 | G29: [Claude 점검 · 고침] '끝내야 할 것'이 관계 종료 권유나 위기 상황에서 위험하게 읽힐 수 있음 (전: 끝내야 할 것을 아직 놓지 못하고 있어요.) | H29: =LEN(IF(F29<>"",F29,D29)) -> 22 | I29: =IF(OR(H29<12,H29>60),"분량 확인","")
A30: cards.14.core | B30: 14 물과 뭍 사이 · 개구리 | C30: 핵심 메시지 · 정방향 | D30: 양쪽 다 내 삶이에요. 알맞게 섞으면 돼요. | E30: 초안 | H30: =LEN(IF(F30<>"",F30,D30)) -> 24 | I30: =IF(OR(H30<12,H30>60),"분량 확인","")
A31: cards.14.reversed.core | B31: 14 물과 뭍 사이 · 개구리 | C31: 핵심 메시지 · 역방향 | D31: 한쪽으로 치우쳐 균형이 흔들리고 있어요. | E31: 초안 | H31: =LEN(IF(F31<>"",F31,D31)) -> 22 | I31: =IF(OR(H31<12,H31>60),"분량 확인","")
A32: cards.15.core | B32: 15 부풀어 오른 마음 · 복어 | C32: 핵심 메시지 · 정방향 | D32: 나를 지키려던 가시가 나를 묶고 있지 않은지 살펴봐요. | E32: 초안 | H32: =LEN(IF(F32<>"",F32,D32)) -> 30 | I32: =IF(OR(H32<12,H32>60),"분량 확인","")
A33: cards.15.reversed.core | B33: 15 부풀어 오른 마음 · 복어 | C33: 핵심 메시지 · 역방향 | D33: 나를 묶던 방어가 조금씩 풀리기 시작해요. | E33: 초안 | H33: =LEN(IF(F33<>"",F33,D33)) -> 23 | I33: =IF(OR(H33<12,H33>60),"분량 확인","")
A34: cards.16.core | B34: 16 다시 쌓는 둑 · 비버 | C34: 핵심 메시지 · 정방향 | D34: 무너진 자리는 다시 쌓을 수 있는 자리이기도 해요. | E34: 초안 | H34: =LEN(IF(F34<>"",F34,D34)) -> 28 | I34: =IF(OR(H34<12,H34>60),"분량 확인","")
A35: cards.16.reversed.core | B35: 16 다시 쌓는 둑 · 비버 | C35: 핵심 메시지 · 역방향 | D35: 무너지지 않으려 애쓰느라 더 지쳐 있어요. | E35: 초안 | H35: =LEN(IF(F35<>"",F35,D35)) -> 23 | I35: =IF(OR(H35<12,H35>60),"분량 확인","")
A36: cards.17.core | B36: 17 다시 빛나는 별 · 불가사리 | C36: 핵심 메시지 · 정방향 | D36: 천천히, 그래도 조금씩 회복은 일어날 수 있어요. | E36: 초안 | G36: [Claude 점검 · 고침] '분명히'로 회복을 단정 (전: 천천히, 그러나 분명히 회복은 일어나요.) | H36: =LEN(IF(F36<>"",F36,D36)) -> 27 | I36: =IF(OR(H36<12,H36>60),"분량 확인","")
A37: cards.17.reversed.core | B37: 17 다시 빛나는 별 · 불가사리 | C37: 핵심 메시지 · 역방향 | D37: 회복의 빛이 아직 희미하게 느껴져요. | E37: 초안 | H37: =LEN(IF(F37<>"",F37,D37)) -> 20 | I37: =IF(OR(H37<12,H37>60),"분량 확인","")
A38: cards.18.core | B38: 18 달빛 아래 떠다니기 · 해파리 | C38: 핵심 메시지 · 정방향 | D38: 다 보이지 않아도 한 걸음씩은 갈 수 있어요. | E38: 초안 | H38: =LEN(IF(F38<>"",F38,D38)) -> 25 | I38: =IF(OR(H38<12,H38>60),"분량 확인","")
A39: cards.18.reversed.core | B39: 18 달빛 아래 떠다니기 · 해파리 | C39: 핵심 메시지 · 역방향 | D39: 안개가 조금씩 걷히기 시작해요. | E39: 초안 | H39: =LEN(IF(F39<>"",F39,D39)) -> 17 | I39: =IF(OR(H39<12,H39>60),"분량 확인","")
A40: cards.19.core | B40: 19 햇살 바위 · 물개 | C40: 핵심 메시지 · 정방향 | D40: 지금 여기의 따뜻함을 충분히 누려도 돼요. | E40: 초안 | H40: =LEN(IF(F40<>"",F40,D40)) -> 23 | I40: =IF(OR(H40<12,H40>60),"분량 확인","")
...

Sheet 카드설명
A1: ID (수정 금지) | B1: 카드 · 분류 | C1: 항목 | D1: 현재 문장 (초안) | E1: 상태 | F1: 수정안 | G1: 검수 메모 | H1: 최종 글자 수 | I1: 분량
A2: cards.0.about_when | B2: 00 첫 물장구 · 수달 | C2: 이럴 때를 비추는 카드 | D2: 무언가를 새로 시작하고 싶거나 낯선 길 앞에 서 있을 때를 비추는 카드예요. | E2: 초안 | H2: =LEN(IF(F2<>"",F2,D2)) -> 42 | I2: =IF(OR(H2<20,H2>140),"분량 확인","")
A3: cards.0.about_origin | B3: 00 첫 물장구 · 수달 | C3: 원래 타로 자리의 뜻 + 쏠 타로식 해석 | D3: 원래 타로의 '바보' 카드 자리로, 전통적으로 순수한 출발과 모험을 뜻해요. 쏠 타로에서는 완벽하게 준비되지 않아도 내딛는 첫걸음의 용기로 읽어요. | E3: 초안 | G3: [Claude 점검 · 고침] 한 문장 안 '뜻합니다'와 '읽어요' 어체 섞임 (전: 원래 타로의 '바보' 카드 자리로, 전통적으로 순수한 출발과 모험을 뜻합니다. 쏠 타로에서는 완벽하게 준비되지 않아도 내딛는 첫걸음의 용기로 읽어요.) | H3: =LEN(IF(F3<>"",F3,D3)) -> 82 | I3: =IF(OR(H3<20,H3>140),"분량 확인","")
A4: cards.1.about_when | B4: 01 여덟 갈래의 손 · 문어 | C4: 이럴 때를 비추는 카드 | D4: 해야 할 일과 할 수 있는 일이 한꺼번에 많을 때를 비추는 카드예요. | E4: 초안 | H4: =LEN(IF(F4<>"",F4,D4)) -> 38 | I4: =IF(OR(H4<20,H4>140),"분량 확인","")
A5: cards.1.about_origin | B5: 01 여덟 갈래의 손 · 문어 | C5: 원래 타로 자리의 뜻 + 쏠 타로식 해석 | D5: 원래 타로의 '마법사' 카드 자리로, 가진 재능과 도구로 무언가를 이뤄 내는 힘을 뜻해요. 쏠 타로에서는 이미 내 손에 있는 자원을 알아보는 힘으로 읽어요. | E5: 초안 | G5: [Claude 점검 · 고침] 한 문장 안 '뜻합니다'와 '읽어요' 어체 섞임 (전: 원래 타로의 '마법사' 카드 자리로, 가진 재능과 도구로 무언가를 이뤄 내는 힘을 뜻합니다. 쏠 타로에서는 이미 내 손에 있는 자원을 알아보는 힘으로 읽어요.) | H5: =LEN(IF(F5<>"",F5,D5)) -> 87 | I5: =IF(OR(H5<20,H5>140),"분량 확인","")
A6: cards.2.about_when | B6: 02 고요히 바라보기 · 왜가리 | C6: 이럴 때를 비추는 카드 | D6: 생각은 많은데 마음이 어디로 기우는지 잘 모를 때를 비추는 카드예요. | E6: 초안 | H6: =LEN(IF(F6<>"",F6,D6)) -> 38 | I6: =IF(OR(H6<20,H6>140),"분량 확인","")
A7: cards.2.about_origin | B7: 02 고요히 바라보기 · 왜가리 | C7: 원래 타로 자리의 뜻 + 쏠 타로식 해석 | D7: 원래 타로의 '여사제' 카드 자리로, 직관과 내면의 지혜, 아직 드러나지 않은 앎을 뜻해요. 쏠 타로에서는 조용히 바라볼 때 들리는 내 안의 목소리로 읽어요. | E7: 초안 | G7: [Claude 점검 · 고침] 한 문장 안 '뜻합니다'와 '읽어요' 어체 섞임 (전: 원래 타로의 '여사제' 카드 자리로, 직관과 내면의 지혜, 아직 드러나지 않은 앎을 뜻합니다. 쏠 타로에서는 조용히 바라볼 때 들리는 내 안의 목소리로 읽어요.) | H7: =LEN(IF(F7<>"",F7,D7)) -> 88 | I7: =IF(OR(H7<20,H7>140),"분량 확인","")
A8: cards.3.about_when | B8: 03 품어 주는 품 · 해달 | C8: 이럴 때를 비추는 카드 | D8: 누군가를 돌보느라 정작 나는 비어 갈 때를 비추는 카드예요. | E8: 초안 | H8: =LEN(IF(F8<>"",F8,D8)) -> 33 | I8: =IF(OR(H8<20,H8>140),"분량 확인","")
A9: cards.3.about_origin | B9: 03 품어 주는 품 · 해달 | C9: 원래 타로 자리의 뜻 + 쏠 타로식 해석 | D9: 원래 타로의 '여황제' 카드 자리로, 풍요와 돌봄, 무언가를 길러 내는 힘을 뜻해요. 쏠 타로에서는 남을 품듯 나를 품어 주는 자기돌봄으로 읽어요. | E9: 초안 | G9: [Claude 점검 · 고침] 한 문장 안 '뜻합니다'와 '읽어요' 어체 섞임 (전: 원래 타로의 '여황제' 카드 자리로, 풍요와 돌봄, 무언가를 길러 내는 힘을 뜻합니다. 쏠 타로에서는 남을 품듯 나를 품어 주는 자기돌봄으로 읽어요.) | H9: =LEN(IF(F9<>"",F9,D9)) -> 82 | I9: =IF(OR(H9<20,H9>140),"분량 확인","")
A10: cards.4.about_when | B10: 04 지키는 자리 · 펭귄 | C10: 이럴 때를 비추는 카드 | D10: 책임이 무겁거나 지켜야 할 것이 많을 때를 비추는 카드예요. | E10: 초안 | H10: =LEN(IF(F10<>"",F10,D10)) -> 33 | I10: =IF(OR(H10<20,H10>140),"분량 확인","")
A11: cards.4.about_origin | B11: 04 지키는 자리 · 펭귄 | C11: 원래 타로 자리의 뜻 + 쏠 타로식 해석 | D11: 원래 타로의 '황제' 카드 자리로, 질서와 책임, 든든한 구조를 뜻해요. 쏠 타로에서는 흔들릴 때 나를 지켜 주는 작은 질서로 읽어요. | E11: 초안 | G11: [Claude 점검 · 고침] 한 문장 안 '뜻합니다'와 '읽어요' 어체 섞임 (전: 원래 타로의 '황제' 카드 자리로, 질서와 책임, 든든한 구조를 뜻합니다. 쏠 타로에서는 흔들릴 때 나를 지켜 주는 작은 질서로 읽어요.) | H11: =LEN(IF(F11<>"",F11,D11)) -> 75 | I11: =IF(OR(H11<20,H11>140),"분량 확인","")
A12: cards.5.about_when | B12: 05 오래된 지혜 · 거북 | C12: 이럴 때를 비추는 카드 | D12: 혼자 답을 찾느라 오래 맴돌고 있을 때를 비추는 카드예요. | E12: 초안 | H12: =LEN(IF(F12<>"",F12,D12)) -> 32 | I12: =IF(OR(H12<20,H12>140),"분량 확인","")
A13: cards.5.about_origin | B13: 05 오래된 지혜 · 거북 | C13: 원래 타로 자리의 뜻 + 쏠 타로식 해석 | D13: 원래 타로의 '교황' 카드 자리로, 전통과 가르침, 믿을 만한 조언을 뜻해요. 쏠 타로에서는 혼자 짊어지지 않고 지혜에 기대는 힘으로 읽어요. | E13: 초안 | G13: [Claude 점검 · 고침] 한 문장 안 '뜻합니다'와 '읽어요' 어체 섞임 (전: 원래 타로의 '교황' 카드 자리로, 전통과 가르침, 믿을 만한 조언을 뜻합니다. 쏠 타로에서는 혼자 짊어지지 않고 지혜에 기대는 힘으로 읽어요.) | H13: =LEN(IF(F13<>"",F13,D13)) -> 79 | I13: =IF(OR(H13<20,H13>140),"분량 확인","")
A14: cards.6.about_when | B14: 06 나란히 헤엄 · 원앙 | C14: 이럴 때를 비추는 카드 | D14: 누군가와의 관계나 중요한 선택 앞에서 마음이 오갈 때를 비추는 카드예요. | E14: 초안 | H14: =LEN(IF(F14<>"",F14,D14)) -> 40 | I14: =IF(OR(H14<20,H14>140),"분량 확인","")
A15: cards.6.about_origin | B15: 06 나란히 헤엄 · 원앙 | C15: 원래 타로 자리의 뜻 + 쏠 타로식 해석 | D15: 원래 타로의 '연인' 카드 자리로, 사랑과 조화, 그리고 가치에 따른 선택을 뜻해요. 쏠 타로에서는 나다운 가치에서 시작하는 연결로 읽어요. | E15: 초안 | G15: [Claude 점검 · 고침] 한 문장 안 '뜻합니다'와 '읽어요' 어체 섞임 (전: 원래 타로의 '연인' 카드 자리로, 사랑과 조화, 그리고 가치에 따른 선택을 뜻합니다. 쏠 타로에서는 나다운 가치에서 시작하는 연결로 읽어요.) | H15: =LEN(IF(F15<>"",F15,D15)) -> 78 | I15: =IF(OR(H15<20,H15>140),"분량 확인","")
A16: cards.7.about_when | B16: 07 파도를 타는 힘 · 돌고래 | C16: 이럴 때를 비추는 카드 | D16: 앞으로 나아가고 싶은 마음이 차오를 때를 비추는 카드예요. | E16: 초안 | H16: =LEN(IF(F16<>"",F16,D16)) -> 32 | I16: =IF(OR(H16<20,H16>140),"분량 확인","")
A17: cards.7.about_origin | B17: 07 파도를 타는 힘 · 돌고래 | C17: 원래 타로 자리의 뜻 + 쏠 타로식 해석 | D17: 원래 타로의 '전차' 카드 자리로, 의지와 추진력, 방향을 잡고 나아가는 힘을 뜻해요. 쏠 타로에서는 거스르기보다 흐름을 타고 나아가는 힘으로 읽어요. | E17: 초안 | G17: [Claude 점검 · 고침] 한 문장 안 '뜻합니다'와 '읽어요' 어체 섞임 (전: 원래 타로의 '전차' 카드 자리로, 의지와 추진력, 방향을 잡고 나아가는 힘을 뜻합니다. 쏠 타로에서는 거스르기보다 흐름을 타고 나아가는 힘으로 읽어요.) | H17: =LEN(IF(F17<>"",F17,D17)) -> 84 | I17: =IF(OR(H17<20,H17>140),"분량 확인","")
A18: cards.8.about_when | B18: 08 진주를 품는 힘 · 조개 | C18: 이럴 때를 비추는 카드 | D18: 불편한 마음을 오래 견디고 있을 때를 비추는 카드예요. | E18: 초안 | H18: =LEN(IF(F18<>"",F18,D18)) -> 30 | I18: =IF(OR(H18<20,H18>140),"분량 확인","")
A19: cards.8.about_origin | B19: 08 진주를 품는 힘 · 조개 | C19: 원래 타로 자리의 뜻 + 쏠 타로식 해석 | D19: 원래 타로의 '힘' 카드 자리로, 부드러움으로 거친 것을 다스리는 내면의 힘을 뜻해요. 쏠 타로에서는 불편함을 품어 단단해지는 힘으로 읽어요. | E19: 초안 | G19: [Claude 점검 · 고침] 한 문장 안 '뜻합니다'와 '읽어요' 어체 섞임 (전: 원래 타로의 '힘' 카드 자리로, 부드러움으로 거친 것을 다스리는 내면의 힘을 뜻합니다. 쏠 타로에서는 불편함을 품어 단단해지는 힘으로 읽어요.) | H19: =LEN(IF(F19<>"",F19,D19)) -> 79 | I19: =IF(OR(H19<20,H19>140),"분량 확인","")
A20: cards.9.about_when | B20: 09 나만의 등불 · 바다의 노인 | C20: 이럴 때를 비추는 카드 | D20: 사람들 사이에서 잠시 물러나 생각할 시간이 필요할 때를 비추는 카드예요. | E20: 초안 | H20: =LEN(IF(F20<>"",F20,D20)) -> 40 | I20: =IF(OR(H20<20,H20>140),"분량 확인","")
A21: cards.9.about_origin | B21: 09 나만의 등불 · 바다의 노인 | C21: 원래 타로 자리의 뜻 + 쏠 타로식 해석 | D21: 원래 타로의 '은둔자' 카드 자리로, 고독 속의 성찰과 내면을 비추는 등불을 뜻해요. 쏠 타로에서는 혼자만의 시간을 나를 비추는 시간으로 바꾸는 힘으로 읽어요. | E21: 초안 | G21: [Claude 점검 · 고침] 한 문장 안 '뜻합니다'와 '읽어요' 어체 섞임 (전: 원래 타로의 '은둔자' 카드 자리로, 고독 속의 성찰과 내면을 비추는 등불을 뜻합니다. 쏠 타로에서는 혼자만의 시간을 나를 비추는 시간으로 바꾸는 힘으로 읽어요.) | H21: =LEN(IF(F21<>"",F21,D21)) -> 89 | I21: =IF(OR(H21<20,H21>140),"분량 확인","")
A22: cards.10.about_when | B22: 10 물살의 순환 · 가오리 | C22: 이럴 때를 비추는 카드 | D22: 내 뜻과 상관없이 상황이 바뀌고 있을 때를 비추는 카드예요. | E22: 초안 | H22: =LEN(IF(F22<>"",F22,D22)) -> 33 | I22: =IF(OR(H22<20,H22>140),"분량 확인","")
A23: cards.10.about_origin | B23: 10 물살의 순환 · 가오리 | C23: 원래 타로 자리의 뜻 + 쏠 타로식 해석 | D23: 원래 타로의 '수레바퀴' 카드 자리로, 돌고 도는 삶의 흐름과 변화의 시기를 뜻해요. 쏠 타로에서는 바뀌는 흐름 속에서 내가 고를 수 있는 움직임으로 읽어요. | E23: 초안 | G23: [Claude 점검 · 고침] 한 문장 안 '뜻합니다'와 '읽어요' 어체 섞임 (전: 원래 타로의 열 번째 카드, 수레바퀴 자리로, 돌고 도는 삶의 흐름과 변화의 시기를 뜻합니다. 쏠 타로에서는 바뀌는 흐름 속에서 내가 고를 수 있는 움직임으로 읽어요.) | H23: =LEN(IF(F23<>"",F23,D23)) -> 88 | I23: =IF(OR(H23<20,H23>140),"분량 확인","")
A24: cards.11.about_when | B24: 11 고요한 균형 · 백조 | C24: 이럴 때를 비추는 카드 | D24: 옳고 그름을 따지거나 공정함이 마음에 걸릴 때를 비추는 카드예요. | E24: 초안 | H24: =LEN(IF(F24<>"",F24,D24)) -> 36 | I24: =IF(OR(H24<20,H24>140),"분량 확인","")
A25: cards.11.about_origin | B25: 11 고요한 균형 · 백조 | C25: 원래 타로 자리의 뜻 + 쏠 타로식 해석 | D25: 원래 타로의 '정의' 카드 자리로, 균형과 공정, 원인과 결과를 뜻해요. 쏠 타로에서는 나에게도 공정한 저울을 내미는 마음으로 읽어요. | E25: 초안 | G25: [Claude 점검 · 고침] 한 문장 안 '뜻합니다'와 '읽어요' 어체 섞임 (전: 원래 타로의 '정의' 카드 자리로, 균형과 공정, 원인과 결과를 뜻합니다. 쏠 타로에서는 나에게도 공정한 저울을 내미는 마음으로 읽어요.) | H25: =LEN(IF(F25<>"",F25,D25)) -> 75 | I25: =IF(OR(H25<20,H25>140),"분량 확인","")
A26: cards.12.about_when | B26: 12 바위 위의 쉼 · 물범 | C26: 이럴 때를 비추는 카드 | D26: 애써도 앞으로 나아가지 않는 것 같고 쉬고 싶을 때를 비추는 카드예요. | E26: 초안 | H26: =LEN(IF(F26<>"",F26,D26)) -> 39 | I26: =IF(OR(H26<20,H26>140),"분량 확인","")
A27: cards.12.about_origin | B27: 12 바위 위의 쉼 · 물범 | C27: 원래 타로 자리의 뜻 + 쏠 타로식 해석 | D27: 원래 타로의 '매달린 사람' 카드 자리로, 멈춤과 기다림, 새로운 관점을 뜻해요. 쏠 타로에서는 다르게 보기 위한 쉼으로 읽어요. | E27: 초안 | G27: [Claude 점검 · 고침] 한 문장 안 '뜻합니다'와 '읽어요' 어체 섞임 (전: 원래 타로의 '매달린 사람' 카드 자리로, 멈춤과 기다림, 다르게 보기를 뜻합니다. 쏠 타로에서는 다르게 보기 위한 쉼으로 읽어요.) | H27: =LEN(IF(F27<>"",F27,D27)) -> 72 | I27: =IF(OR(H27<20,H27>140),"분량 확인","")
A28: cards.13.about_when | B28: 13 새 집으로 이사 · 소라게 | C28: 이럴 때를 비추는 카드 | D28: 무언가가 끝나 가거나 바뀌어야 할 때를 비추는 카드예요. | E28: 초안 | H28: =LEN(IF(F28<>"",F28,D28)) -> 31 | I28: =IF(OR(H28<20,H28>140),"분량 확인","")
A29: cards.13.about_origin | B29: 13 새 집으로 이사 · 소라게 | C29: 원래 타로 자리의 뜻 + 쏠 타로식 해석 | D29: 원래 타로의 열세 번째 카드 자리로, 한 시기의 끝과 새로운 시작을 뜻해요. 쏠 타로에서는 맞지 않는 껍데기를 내려놓고 새 집으로 옮겨 가는 전환으로 읽어요. | E29: 초안 | G29: [Claude 점검 · 고침] 한 문장 안 '뜻합니다'와 '읽어요' 어체 섞임 (전: 원래 타로의 열세 번째 카드 자리로, 한 시기의 끝과 새로운 시작을 뜻합니다. 쏠 타로에서는 맞지 않는 껍데기를 내려놓고 새 집으로 옮겨 가는 전환으로 읽어요.) | H29: =LEN(IF(F29<>"",F29,D29)) -> 88 | I29: =IF(OR(H29<20,H29>140),"분량 확인","")
A30: cards.14.about_when | B30: 14 물과 뭍 사이 · 개구리 | C30: 이럴 때를 비추는 카드 | D30: 두 가지 사이에서 균형을 찾느라 지칠 때를 비추는 카드예요. | E30: 초안 | H30: =LEN(IF(F30<>"",F30,D30)) -> 33 | I30: =IF(OR(H30<20,H30>140),"분량 확인","")
A31: cards.14.about_origin | B31: 14 물과 뭍 사이 · 개구리 | C31: 원래 타로 자리의 뜻 + 쏠 타로식 해석 | D31: 원래 타로의 '절제' 카드 자리로, 조화와 알맞음, 서로 다른 것을 섞는 지혜를 뜻해요. 쏠 타로에서는 둘 중 하나가 아니라 알맞은 비율을 찾는 힘으로 읽어요. | E31: 초안 | G31: [Claude 점검 · 고침] 한 문장 안 '뜻합니다'와 '읽어요' 어체 섞임 (전: 원래 타로의 '절제' 카드 자리로, 조화와 알맞음, 서로 다른 것을 섞는 지혜를 뜻합니다. 쏠 타로에서는 둘 중 하나가 아니라 알맞은 비율을 찾는 힘으로 읽어요.) | H31: =LEN(IF(F31<>"",F31,D31)) -> 89 | I31: =IF(OR(H31<20,H31>140),"분량 확인","")
A32: cards.15.about_when | B32: 15 부풀어 오른 마음 · 복어 | C32: 이럴 때를 비추는 카드 | D32: 불안할 때 반복하는 습관이나 방어가 마음을 묶고 있을 때를 비추는 카드예요. | E32: 초안 | H32: =LEN(IF(F32<>"",F32,D32)) -> 42 | I32: =IF(OR(H32<20,H32>140),"분량 확인","")
A33: cards.15.about_origin | B33: 15 부풀어 오른 마음 · 복어 | C33: 원래 타로 자리의 뜻 + 쏠 타로식 해석 | D33: 원래 타로의 열다섯 번째 카드 자리로, 나를 얽매는 집착과 습관을 뜻해요. 쏠 타로에서는 나를 지키려던 가시를 알아차리는 일로 읽어요. | E33: 초안 | G33: [Claude 점검 · 고침] 한 문장 안 '뜻합니다'와 '읽어요' 어체 섞임 (전: 원래 타로의 열다섯 번째 카드 자리로, 나를 얽매는 집착과 습관을 뜻합니다. 쏠 타로에서는 나를 지키려던 가시를 알아차리는 일로 읽어요.) | H33: =LEN(IF(F33<>"",F33,D33)) -> 75 | I33: =IF(OR(H33<20,H33>140),"분량 확인","")
A34: cards.16.about_when | B34: 16 다시 쌓는 둑 · 비버 | C34: 이럴 때를 비추는 카드 | D34: 믿어 온 계획이 흔들리거나 갑자기 무너졌을 때를 비추는 카드예요. | E34: 초안 | H34: =LEN(IF(F34<>"",F34,D34)) -> 36 | I34: =IF(OR(H34<20,H34>140),"분량 확인","")
A35: cards.16.about_origin | B35: 16 다시 쌓는 둑 · 비버 | C35: 원래 타로 자리의 뜻 + 쏠 타로식 해석 | D35: 원래 타로의 '탑' 카드 자리로, 예상치 못한 변화와 그 뒤에 오는 새로운 깨달음을 뜻해요. 쏠 타로에서는 무너진 자리에서 다시 쌓는 회복의 힘으로 읽어요. | E35: 초안 | G35: [Claude 점검 · 고침] 한 문장 안 '뜻합니다'와 '읽어요' 어체 섞임 (전: 원래 타로의 '탑' 카드 자리로, 예상치 못한 변화와 그 뒤에 오는 새로운 깨달음을 뜻합니다. 쏠 타로에서는 무너진 자리에서 다시 쌓는 회복의 힘으로 읽어요.) | H35: =LEN(IF(F35<>"",F35,D35)) -> 87 | I35: =IF(OR(H35<20,H35>140),"분량 확인","")
A36: cards.17.about_when | B36: 17 다시 빛나는 별 · 불가사리 | C36: 이럴 때를 비추는 카드 | D36: 힘든 시간을 지나 조금씩 숨이 돌아올 때를 비추는 카드예요. | E36: 초안 | H36: =LEN(IF(F36<>"",F36,D36)) -> 33 | I36: =IF(OR(H36<20,H36>140),"분량 확인","")
A37: cards.17.about_origin | B37: 17 다시 빛나는 별 · 불가사리 | C37: 원래 타로 자리의 뜻 + 쏠 타로식 해석 | D37: 원래 타로의 '별' 카드 자리로, 희망과 치유, 다시 찾아오는 빛을 뜻해요. 쏠 타로에서는 천천히 자라는 회복으로 읽어요. | E37: 초안 | G37: [Claude 점검 · 고침] 한 문장 안 '뜻합니다'와 '읽어요' 어체 섞임 (전: 원래 타로의 '별' 카드 자리로, 희망과 치유, 다시 찾아오는 빛을 뜻합니다. 쏠 타로에서는 천천히 자라는 회복으로 읽어요.) | H37: =LEN(IF(F37<>"",F37,D37)) -> 68 | I37: =IF(OR(H37<20,H37>140),"분량 확인","")
A38: cards.18.about_when | B38: 18 달빛 아래 떠다니기 · 해파리 | C38: 이럴 때를 비추는 카드 | D38: 앞이 잘 보이지 않아 막연히 불안할 때를 비추는 카드예요. | E38: 초안 | H38: =LEN(IF(F38<>"",F38,D38)) -> 32 | I38: =IF(OR(H38<20,H38>140),"분량 확인","")
A39: cards.18.about_origin | B39: 18 달빛 아래 떠다니기 · 해파리 | C39: 원래 타로 자리의 뜻 + 쏠 타로식 해석 | D39: 원래 타로의 '달' 카드 자리로, 불확실함과 상상, 드러나지 않은 마음을 뜻해요. 쏠 타로에서는 다 보이지 않아도 한 걸음씩 가는 힘으로 읽어요. | E39: 초안 | G39: [Claude 점검 · 고침] 한 문장 안 '뜻합니다'와 '읽어요' 어체 섞임 (전: 원래 타로의 '달' 카드 자리로, 불확실함과 상상, 드러나지 않은 마음을 뜻합니다. 쏠 타로에서는 다 보이지 않아도 한 걸음씩 가는 힘으로 읽어요.) | H39: =LEN(IF(F39<>"",F39,D39)) -> 81 | I39: =IF(OR(H39<20,H39>140),"분량 확인","")
A40: cards.19.about_when | B40: 19 햇살 바위 · 물개 | C40: 이럴 때를 비추는 카드 | D40: 고민 속에서도 기쁨과 기대가 살아 있을 때를 비추는 카드예요. | E40: 초안 | H40: =LEN(IF(F40<>"",F40,D40)) -> 34 | I40: =IF(OR(H40<20,H40>140),"분량 확인","")
...

Sheet 상황질문
A1: ID (수정 금지) | B1: 카드 · 분류 | C1: 항목 | D1: 현재 문장 (초안) | E1: 상태 | F1: 수정안 | G1: 검수 메모 | H1: 최종 글자 수 | I1: 분량
A2: cards.0.asks.0 | B2: 00 첫 물장구 · 수달 | C2: 기본 질문 1 | D2: 하고 싶은 일이 있는데 '좀 더 준비되면'이라며 미루고 있진 않나요? | E2: 초안 | H2: =LEN(IF(F2<>"",F2,D2)) -> 38 | I2: =IF(OR(H2<15,H2>90),"분량 확인","")
A3: cards.0.asks.1 | B3: 00 첫 물장구 · 수달 | C3: 기본 질문 2 | D3: 처음이라 서툴까 봐 시작 앞에서 오래 서성인 적, 최근에 있지 않았나요? | E3: 초안 | H3: =LEN(IF(F3<>"",F3,D3)) -> 40 | I3: =IF(OR(H3<15,H3>90),"분량 확인","")
A4: cards.0.reversed.asks.0 | B4: 00 첫 물장구 · 수달 | C4: 기본 질문 1 · 역방향 | D4: 하고 싶은 일 앞에서 '실패하면 어쩌지'가 먼저 떠오르진 않나요? | E4: 초안 | H4: =LEN(IF(F4<>"",F4,D4)) -> 36 | I4: =IF(OR(H4<15,H4>90),"분량 확인","")
A5: cards.0.reversed.asks.1 | B5: 00 첫 물장구 · 수달 | C5: 기본 질문 2 · 역방향 | D5: 처음부터 잘해야 한다는 생각에 시작을 몇 번이나 미뤄 왔나요? | E5: 초안 | H5: =LEN(IF(F5<>"",F5,D5)) -> 34 | I5: =IF(OR(H5<15,H5>90),"분량 확인","")
A6: cards.1.asks.0 | B6: 01 여덟 갈래의 손 · 문어 | C6: 기본 질문 1 | D6: 할 일은 많은데 어디서부터 손대야 할지 몰라 하루가 그냥 지나가곤 하나요? | E6: 초안 | H6: =LEN(IF(F6<>"",F6,D6)) -> 41 | I6: =IF(OR(H6<15,H6>90),"분량 확인","")
A7: cards.1.asks.1 | B7: 01 여덟 갈래의 손 · 문어 | C7: 기본 질문 2 | D7: 이미 잘하고 있는 것보다 부족한 것이 먼저 눈에 들어오진 않으세요? | E7: 초안 | H7: =LEN(IF(F7<>"",F7,D7)) -> 37 | I7: =IF(OR(H7<15,H7>90),"분량 확인","")
A8: cards.1.reversed.asks.0 | B8: 01 여덟 갈래의 손 · 문어 | C8: 기본 질문 1 · 역방향 | D8: 할 일은 많은데 정작 하나도 제대로 못 한 것 같은 날이 이어지고 있나요? | E8: 초안 | H8: =LEN(IF(F8<>"",F8,D8)) -> 41 | I8: =IF(OR(H8<15,H8>90),"분량 확인","")
A9: cards.1.reversed.asks.1 | B9: 01 여덟 갈래의 손 · 문어 | C9: 기본 질문 2 · 역방향 | D9: 모든 걸 다 챙기려다 정작 중요한 일에 힘이 남지 않은 적 없었나요? | E9: 초안 | H9: =LEN(IF(F9<>"",F9,D9)) -> 38 | I9: =IF(OR(H9<15,H9>90),"분량 확인","")
A10: cards.2.asks.0 | B10: 02 고요히 바라보기 · 왜가리 | C10: 기본 질문 1 | D10: 여러 사람에게 조언을 구했는데 오히려 더 헷갈렸던 적은 없나요? | E10: 초안 | H10: =LEN(IF(F10<>"",F10,D10)) -> 35 | I10: =IF(OR(H10<15,H10>90),"분량 확인","")
A11: cards.2.asks.1 | B11: 02 고요히 바라보기 · 왜가리 | C11: 기본 질문 2 | D11: 마음이 한쪽으로 기우는 것 같은데, 그 마음을 믿어도 될지 망설이고 있나요? | E11: 초안 | G11: [Claude 점검 · 고침] '마음은 이미 한쪽으로 기울어 있는데'로 사실을 단정하며, 같은 카드 설명('마음이 어디로 기우는지 잘 모를 때')과 충돌 (전: 마음은 이미 한쪽으로 기울어 있는데, 그 마음을 믿어도 될지 망설이고 있나요?) | H11: =LEN(IF(F11<>"",F11,D11)) -> 42 | I11: =IF(OR(H11<15,H11>90),"분량 확인","")
A12: cards.2.reversed.asks.0 | B12: 02 고요히 바라보기 · 왜가리 | C12: 기본 질문 1 · 역방향 | D12: 결정을 앞두고 검색하고 묻는 사이, 내 마음은 어디에 있는지 놓친 적 있나요? | E12: 초안 | H12: =LEN(IF(F12<>"",F12,D12)) -> 43 | I12: =IF(OR(H12<15,H12>90),"분량 확인","")
A13: cards.2.reversed.asks.1 | B13: 02 고요히 바라보기 · 왜가리 | C13: 기본 질문 2 · 역방향 | D13: 느낌으로는 알 것 같은데, 애써 모른 척하고 있는 일이 있진 않나요? | E13: 초안 | H13: =LEN(IF(F13<>"",F13,D13)) -> 38 | I13: =IF(OR(H13<15,H13>90),"분량 확인","")
A14: cards.3.asks.0 | B14: 03 품어 주는 품 · 해달 | C14: 기본 질문 1 | D14: 다른 사람 일은 먼저 챙기면서 내 끼니나 잠은 자주 뒤로 미루고 있진 않나요? | E14: 초안 | H14: =LEN(IF(F14<>"",F14,D14)) -> 43 | I14: =IF(OR(H14<15,H14>90),"분량 확인","")
A15: cards.3.asks.1 | B15: 03 품어 주는 품 · 해달 | C15: 기본 질문 2 | D15: '괜찮아'라는 말이 습관이 되어, 정작 도움을 받기는 어렵지 않으세요? | E15: 초안 | H15: =LEN(IF(F15<>"",F15,D15)) -> 39 | I15: =IF(OR(H15<15,H15>90),"분량 확인","")
A16: cards.3.reversed.asks.0 | B16: 03 품어 주는 품 · 해달 | C16: 기본 질문 1 · 역방향 | D16: 누군가 나를 챙겨 줄 때 고맙기보다 미안한 마음이 먼저 들지 않나요? | E16: 초안 | H16: =LEN(IF(F16<>"",F16,D16)) -> 38 | I16: =IF(OR(H16<15,H16>90),"분량 확인","")
A17: cards.3.reversed.asks.1 | B17: 03 품어 주는 품 · 해달 | C17: 기본 질문 2 · 역방향 | D17: 다른 사람을 챙기느라 내 끼니나 잠을 뒤로 미룬 날이 늘고 있진 않나요? | E17: 초안 | H17: =LEN(IF(F17<>"",F17,D17)) -> 40 | I17: =IF(OR(H17<15,H17>90),"분량 확인","")
